Workbook

Sheet Error Checking
B2: =SUM(B3:B9) -> 0 | D2: Master Error Check Cell
B4: =SUM('13 weeks CF'!14:14) -> 0 | D4: Cash Forecast doesn't match Actual data
B5: =SUM('Summary Dashboard'!14:14) -> 0 | D5: Summary doesn't match the Cash Flow Forecast
B6: =SUM('Rolling CF'!14:14) -> 0 | D6: Cash Forecast 02 doesn't match Actual data
B7: =SUM('Variance Analysis'!20:20) -> 0 | D7: Variance Report doesn't match Cash Forecast
D9: Put all additional error checks above this line

Sheet INSTRUCTIONS
B2: File Update Instructions
B3: Last Updated: XX/XX/XXXX
B5: Week Ending | D5: 45269
B7: Save as new version. | D7: x
B9: Duplicate Cash Forecast Tab | D9: x
B11: Bring Error Check to Error Checking Tab | D11: x
B13: Copy/paste last week's forecast to new forecast | D13: x
B15: Bring in new Bank Data. | D15: x
B17: Add Transaction Numbers & drag down helper formulas. | D17: x
B19: Make sure any checks over $3,000 are tagged to AP. | D19: x
B21: Copy AP Aging Report & bring in new data. | D21: x
B23: Copy AR Aging Report & bring in new data. | D23: x
B25: Drag "Actual" along top of new Cash Forecast. | D25: x
B27: Drag forward all SUMIFS formulas. | D27: x
B29: Copy/paste Ending Cash balance (and fix any variances). | D29: x
... B47: Final Review & distribute report. | D47: x

Sheet Summary Dashboard
B2: Master Error Check Cell | C2: ='Error Checking'!$B$2 -> 0
B4: Actual / Forecast | D4: Actual | E4: Actual | F4: Actual | G4: Actual | H4: Actual | I4: Actual | J4: Forecast | K4: Forecast | L4: Forecast | M4: Forecast | N4: Forecast | O4: Forecast | P4: Forecast | Q4: Forecast | R4: Forecast | S4: Forecast | T4: Forecast | U4: Forecast | V4: Forecast
B5: Week Number | D5: 1 | E5: =D5+1 -> 2 | F5: =E5+1 -> 3 | G5: =F5+1 -> 4 | H5: =G5+1 -> 5 | I5: =H5+1 -> 6 | J5: =I5+1 -> 7 | K5: =J5+1 -> 8 | L5: =K5+1 -> 9 | ... V5: =U5+1 -> 19
B6: Week Beginning | D6: =D7-6 -> 45228 | E6: =E7-6 -> 45235 | F6: =F7-6 -> 45242 | G6: =G7-6 -> 45249 | H6: =H7-6 -> 45256 | I6: =I7-6 -> 45263 | J6: =J7-6 -> 45270 | K6: =K7-6 -> 45277 | ... V6: =V7-6 -> 45354
B7: Week Ending | C7: Forecast Methodology | D7: =E6-1 -> 45234 | E7: =F6-1 -> 45241 | F7: =G6-1 -> 45248 | G7: =H6-1 -> 45255 | H7: =I6-1 -> 45262 | I7: =J6-1 -> 45269 | J7: =K6-1 -> 45276 | K7: =L6-1 -> 45283 | ... U7: =V6-1 -> 45353 | V7: =MAX('Rolling CF'!$7:$7) -> 45360
B9: Cash Balance
B10: Beginning Cash | D10: =INDEX('Rolling CF'!$1:$1048576,MATCH($B10,'Rolling CF'!$C:$C,0),MATCH(D$7,'Rolling CF'!$7:$7,0)) -> 210210 | E10: =D12 -> 174090 | F10: =E12 -> 239110 | G10: =F12 -> 43360 | H10: =G12 -> 325260 | I10: =H12 -> 215160 | J10: =I12 -> 108940 | K10: =J12 -> 160208.33 | L10: =K12 -> 489131.39 | ... V10: =U12 -> -137705.13
B11: Change in Cash | D11: =D76 -> -36120 | E11: =E76 -> 65020 | F11: =F76 -> -195750 | G11: =G76 -> 281900 | H11: =H76 -> -110100 | I11: =I76 -> -106220 | J11: =J76 -> 51268.333 | K11: =K76 -> 328923.06 | ... V11: =V76 -> -59244.097
B12: Ending Cash | D12: =SUM(D10:D11) -> 174090 | E12: =SUM(E10:E11) -> 239110 | F12: =SUM(F10:F11) -> 43360 | G12: =SUM(G10:G11) -> 325260 | H12: =SUM(H10:H11) -> 215160 | I12: =SUM(I10:I11) -> 108940 | J12: =SUM(J10:J11) -> 160208.33 | K12: =SUM(K10:K11) -> 489131.39 | ... V12: =SUM(V10:V11) -> -196949.22
B13: Per Data | D13: =INDEX('Rolling CF'!$1:$1048576,MATCH($B13,'Rolling CF'!$C:$C,0),MATCH(D$7,'Rolling CF'!$7:$7,0)) -> 174090 | E13: =INDEX('Rolling CF'!$1:$1048576,MATCH($B13,'Rolling CF'!$C:$C,0),MATCH(E$7,'Rolling CF'!$7:$7,0)) -> 239110 | F13: =INDEX('Rolling CF'!$1:$1048576,MATCH($B13,'Rolling CF'!$C:$C,0),MATCH(F$7,'Rolling CF'!$7:$7,0)) -> 43360 | G13: =INDEX('Rolling CF'!$1:$1048576,MATCH($B13,'Rolling CF'!$C:$C,0),MATCH(G$7,'Rolling CF'!$7:$7,0)) -> 325260 | H13: =INDEX('Rolling CF'!$1:$1048576,MATCH($B13,'Rolling CF'!$C:$C,0),MATCH(H$7,'Rolling CF'!$7:$7,0)) -> 215160 | I13: =INDEX('Rolling CF'!$1:$1048576,MATCH($B13,'Rolling CF'!$C:$C,0),MATCH(I$7,'Rolling CF'!$7:$7,0)) -> 108940 | J13: =INDEX('Rolling CF'!$1:$1048576,MATCH($B13,'Rolling CF'!$C:$C,0),MATCH(J$7,'Rolling CF'!$7:$7,0)) -> 0 | K13: =INDEX('Rolling CF'!$1:$1048576,MATCH($B13,'Rolling CF'!$C:$C,0),MATCH(K$7,'Rolling CF'!$7:$7,0)) -> 0 | ... V13: =INDEX('Rolling CF'!$1:$1048576,MATCH($B13,'Rolling CF'!$C:$C,0),MATCH(V$7,'Rolling CF'!$7:$7,0)) -> 0
B14: Double-Check | D14: =IF(D$4="Forecast",0,D13-D12) -> 0 | E14: =IF(E$4="Forecast",0,E13-E12) -> 0 | F14: =IF(F$4="Forecast",0,F13-F12) -> 0 | G14: =IF(G$4="Forecast",0,G13-G12) -> 0 | H14: =IF(H$4="Forecast",0,H13-H12) -> 0 | I14: =IF(I$4="Forecast",0,I13-I12) -> 0 | J14: =IF(J$4="Forecast",0,J13-J12) -> 0 | K14: =IF(K$4="Forecast",0,K13-K12) -> 0 | ... V14: =IF(V$4="Forecast",0,V13-V12) -> 0
B15: Last Week's Forecast | D15: =INDEX('Rolling CF'!$1:$1048576,MATCH($B15,'Rolling CF'!$C:$C,0),MATCH(D$7,'Rolling CF'!$7:$7,0)) -> 174090 | E15: =INDEX('Rolling CF'!$1:$1048576,MATCH($B15,'Rolling CF'!$C:$C,0),MATCH(E$7,'Rolling CF'!$7:$7,0)) -> 239110 | F15: =INDEX('Rolling CF'!$1:$1048576,MATCH($B15,'Rolling CF'!$C:$C,0),MATCH(F$7,'Rolling CF'!$7:$7,0)) -> 43360 | G15: =INDEX('Rolling CF'!$1:$1048576,MATCH($B15,'Rolling CF'!$C:$C,0),MATCH(G$7,'Rolling CF'!$7:$7,0)) -> 325260 | H15: =INDEX('Rolling CF'!$1:$1048576,MATCH($B15,'Rolling CF'!$C:$C,0),MATCH(H$7,'Rolling CF'!$7:$7,0)) -> 215160 | I15: =INDEX('Rolling CF'!$1:$1048576,MATCH($B15,'Rolling CF'!$C:$C,0),MATCH(I$7,'Rolling CF'!$7:$7,0)) -> 112041.67 | J15: =INDEX('Rolling CF'!$1:$1048576,MATCH($B15,'Rolling CF'!$C:$C,0),MATCH(J$7,'Rolling CF'!$7:$7,0)) -> 156995.28 | K15: =INDEX('Rolling CF'!$1:$1048576,MATCH($B15,'Rolling CF'!$C:$C,0),MATCH(K$7,'Rolling CF'!$7:$7,0)) -> 399451.16 | ... V15: =INDEX('Rolling CF'!$1:$1048576,MATCH($B15,'Rolling CF'!$C:$C,0),MATCH(V$7,'Rolling CF'!$7:$7,0)) -> 0
B34: Cash Inflows
B35: Invoiced AR + New Revenue | C35: See AR Aging Schedule | D35: =INDEX('Rolling CF'!$1:$1048576,MATCH($B35,'Rolling CF'!$C:$C,0),MATCH(D$7,'Rolling CF'!$7:$7,0)) -> 372100 | E35: =INDEX('Rolling CF'!$1:$1048576,MATCH($B35,'Rolling CF'!$C:$C,0),MATCH(E$7,'Rolling CF'!$7:$7,0)) -> 210150 | F35: =INDEX('Rolling CF'!$1:$1048576,MATCH($B35,'Rolling CF'!$C:$C,0),MATCH(F$7,'Rolling CF'!$7:$7,0)) -> 0 | G35: =INDEX('Rolling CF'!$1:$1048576,MATCH($B35,'Rolling CF'!$C:$C,0),MATCH(G$7,'Rolling CF'!$7:$7,0)) -> 361430 | H35: =INDEX('Rolling CF'!$1:$1048576,MATCH($B35,'Rolling CF'!$C:$C,0),MATCH(H$7,'Rolling CF'!$7:$7,0)) -> 68440 | I35: =INDEX('Rolling CF'!$1:$1048576,MATCH($B35,'Rolling CF'!$C:$C,0),MATCH(I$7,'Rolling CF'!$7:$7,0)) -> 389470 | J35: =INDEX('Rolling CF'!$1:$1048576,MATCH($B35,'Rolling CF'!$C:$C,0),MATCH(J$7,'Rolling CF'!$7:$7,0)) -> 120000 | K35: =INDEX('Rolling CF'!$1:$1048576,MATCH($B35,'Rolling CF'!$C:$C,0),MATCH(K$7,'Rolling CF'!$7:$7,0)) -> 554000 | ... V35: =INDEX('Rolling CF'!$1:$1048576,MATCH($B35,'Rolling CF'!$C:$C,0),MATCH(V$7,'Rolling CF'!$7:$7,0)) -> 0
B36: Other Inflows | C36: Enter Manually | D36: =INDEX('Rolling CF'!$1:$1048576,MATCH($B36,'Rolling CF'!$C:$C,0),MATCH(D$7,'Rolling CF'!$7:$7,0)) -> 0 | E36: =INDEX('Rolling CF'!$1:$1048576,MATCH($B36,'Rolling CF'!$C:$C,0),MATCH(E$7,'Rolling CF'!$7:$7,0)) -> 0 | F36: =INDEX('Rolling CF'!$1:$1048576,MATCH($B36,'Rolling CF'!$C:$C,0),MATCH(F$7,'Rolling CF'!$7:$7,0)) -> 0 | G36: =INDEX('Rolling CF'!$1:$1048576,MATCH($B36,'Rolling CF'!$C:$C,0),MATCH(G$7,'Rolling CF'!$7:$7,0)) -> 0 | H36: =INDEX('Rolling CF'!$1:$1048576,MATCH($B36,'Rolling CF'!$C:$C,0),MATCH(H$7,'Rolling CF'!$7:$7,0)) -> 0 | I36: =INDEX('Rolling CF'!$1:$1048576,MATCH($B36,'Rolling CF'!$C:$C,0),MATCH(I$7,'Rolling CF'!$7:$7,0)) -> 0 | J36: =INDEX('Rolling CF'!$1:$1048576,MATCH($B36,'Rolling CF'!$C:$C,0),MATCH(J$7,'Rolling CF'!$7:$7,0)) -> 0 | K36: =INDEX('Rolling CF'!$1:$1048576,MATCH($B36,'Rolling CF'!$C:$C,0),MATCH(K$7,'Rolling CF'!$7:$7,0)) -> 0 | ... V36: =INDEX('Rolling CF'!$1:$1048576,MATCH($B36,'Rolling CF'!$C:$C,0),MATCH(V$7,'Rolling CF'!$7:$7,0)) -> 0
B38: Total Cash Inflows | D38: =SUM(D35:D37) -> 372100 | E38: =SUM(E35:E37) -> 210150 | F38: =SUM(F35:F37) -> 0 | G38: =SUM(G35:G37) -> 361430 | H38: =SUM(H35:H37) -> 68440 | I38: =SUM(I35:I37) -> 389470 | J38: =SUM(J35:J37) -> 120000 | K38: =SUM(K35:K37) -> 554000 | ... V38: =SUM(V35:V37) -> 0
B40: Operating Cash Outflows
B41: Accounts Payable | C41: See AP Aging Schedule | D41: =INDEX('Rolling CF'!$1:$1048576,MATCH($B41,'Rolling CF'!$C:$C,0),MATCH(D$7,'Rolling CF'!$7:$7,0)) -> -83210 | E41: =INDEX('Rolling CF'!$1:$1048576,MATCH($B41,'Rolling CF'!$C:$C,0),MATCH(E$7,'Rolling CF'!$7:$7,0)) -> -69810 | F41: =INDEX('Rolling CF'!$1:$1048576,MATCH($B41,'Rolling CF'!$C:$C,0),MATCH(F$7,'Rolling CF'!$7:$7,0)) -> -40140 | G41: =INDEX('Rolling CF'!$1:$1048576,MATCH($B41,'Rolling CF'!$C:$C,0),MATCH(G$7,'Rolling CF'!$7:$7,0)) -> -18680 | H41: =INDEX('Rolling CF'!$1:$1048576,MATCH($B41,'Rolling CF'!$C:$C,0),MATCH(H$7,'Rolling CF'!$7:$7,0)) -> -88580 | I41: =INDEX('Rolling CF'!$1:$1048576,MATCH($B41,'Rolling CF'!$C:$C,0),MATCH(I$7,'Rolling CF'!$7:$7,0)) -> -89740 | J41: =INDEX('Rolling CF'!$1:$1048576,MATCH($B41,'Rolling CF'!$C:$C,0),MATCH(J$7,'Rolling CF'!$7:$7,0)) -> 0 | K41: =INDEX('Rolling CF'!$1:$1048576,MATCH($B41,'Rolling CF'!$C:$C,0),MATCH(K$7,'Rolling CF'!$7:$7,0)) -> -164600 | ... V41: =INDEX('Rolling CF'!$1:$1048576,MATCH($B41,'Rolling CF'!$C:$C,0),MATCH(V$7,'Rolling CF'!$7:$7,0)) -> 0
B42: Credit Cards | C42: See AP Aging Schedule | D42: =INDEX('Rolling CF'!$1:$1048576,MATCH($B42,'Rolling CF'!$C:$C,0),MATCH(D$7,'Rolling CF'!$7:$7,0)) -> -194090 | E42: =INDEX('Rolling CF'!$1:$1048576,MATCH($B42,'Rolling CF'!$C:$C,0),MATCH(E$7,'Rolling CF'!$7:$7,0)) -> 0 | F42: =INDEX('Rolling CF'!$1:$1048576,MATCH($B42,'Rolling CF'!$C:$C,0),MATCH(F$7,'Rolling CF'!$7:$7,0)) -> -100000 | G42: =INDEX('Rolling CF'!$1:$1048576,MATCH($B42,'Rolling CF'!$C:$C,0),MATCH(G$7,'Rolling CF'!$7:$7,0)) -> 0 | H42: =INDEX('Rolling CF'!$1:$1048576,MATCH($B42,'Rolling CF'!$C:$C,0),MATCH(H$7,'Rolling CF'!$7:$7,0)) -> -32000 | I42: =INDEX('Rolling CF'!$1:$1048576,MATCH($B42,'Rolling CF'!$C:$C,0),MATCH(I$7,'Rolling CF'!$7:$7,0)) -> -350210 | J42: =INDEX('Rolling CF'!$1:$1048576,MATCH($B42,'Rolling CF'!$C:$C,0),MATCH(J$7,'Rolling CF'!$7:$7,0)) -> 0 | K42: =INDEX('Rolling CF'!$1:$1048576,MATCH($B42,'Rolling CF'!$C:$C,0),MATCH(K$7,'Rolling CF'!$7:$7,0)) -> 0 | ... V42: =INDEX('Rolling CF'!$1:$1048576,MATCH($B42,'Rolling CF'!$C:$C,0),MATCH(V$7,'Rolling CF'!$7:$7,0)) -> 0
B43: Payroll | C43: Trailing 6 Week Average | D43: =INDEX('Rolling CF'!$1:$1048576,MATCH($B43,'Rolling CF'!$C:$C,0),MATCH(D$7,'Rolling CF'!$7:$7,0)) -> -78050 | E43: =INDEX('Rolling CF'!$1:$1048576,MATCH($B43,'Rolling CF'!$C:$C,0),MATCH(E$7,'Rolling CF'!$7:$7,0)) -> -51670 | F43: =INDEX('Rolling CF'!$1:$1048576,MATCH($B43,'Rolling CF'!$C:$C,0),MATCH(F$7,'Rolling CF'!$7:$7,0)) -> -39960 | G43: =INDEX('Rolling CF'!$1:$1048576,MATCH($B43,'Rolling CF'!$C:$C,0),MATCH(G$7,'Rolling CF'!$7:$7,0)) -> -44380 | H43: =INDEX('Rolling CF'!$1:$1048576,MATCH($B43,'Rolling CF'!$C:$C,0),MATCH(H$7,'Rolling CF'!$7:$7,0)) -> -35340 | I43: =INDEX('Rolling CF'!$1:$1048576,MATCH($B43,'Rolling CF'!$C:$C,0),MATCH(I$7,'Rolling CF'!$7:$7,0)) -> -35660 | J43: =INDEX('Rolling CF'!$1:$1048576,MATCH($B43,'Rolling CF'!$C:$C,0),MATCH(J$7,'Rolling CF'!$7:$7,0)) -> -47510 | K43: =INDEX('Rolling CF'!$1:$1048576,MATCH($B43,'Rolling CF'!$C:$C,0),MATCH(K$7,'Rolling CF'!$7:$7,0)) -> -42420 | ... V43: =INDEX('Rolling CF'!$1:$1048576,MATCH($B43,'Rolling CF'!$C:$C,0),MATCH(V$7,'Rolling CF'!$7:$7,0)) -> -41500.77
B44: Contractors | C44: Enter Manually | D44: =INDEX('Rolling CF'!$1:$1048576,MATCH($B44,'Rolling CF'!$C:$C,0),MATCH(D$7,'Rolling CF'!$7:$7,0)) -> 0 | E44: =INDEX('Rolling CF'!$1:$1048576,MATCH($B44,'Rolling CF'!$C:$C,0),MATCH(E$7,'Rolling CF'!$7:$7,0)) -> 0 | F44: =INDEX('Rolling CF'!$1:$1048576,MATCH($B44,'Rolling CF'!$C:$C,0),MATCH(F$7,'Rolling CF'!$7:$7,0)) -> 0 | G44: =INDEX('Rolling CF'!$1:$1048576,MATCH($B44,'Rolling CF'!$C:$C,0),MATCH(G$7,'Rolling CF'!$7:$7,0)) -> 0 | H44: =INDEX('Rolling CF'!$1:$1048576,MATCH($B44,'Rolling CF'!$C:$C,0),MATCH(H$7,'Rolling CF'!$7:$7,0)) -> 0 | I44: =INDEX('Rolling CF'!$1:$1048576,MATCH($B44,'Rolling CF'!$C:$C,0),MATCH(I$7,'Rolling CF'!$7:$7,0)) -> 0 | J44: =INDEX('Rolling CF'!$1:$1048576,MATCH($B44,'Rolling CF'!$C:$C,0),MATCH(J$7,'Rolling CF'!$7:$7,0)) -> 0 | K44: =INDEX('Rolling CF'!$1:$1048576,MATCH($B44,'Rolling CF'!$C:$C,0),MATCH(K$7,'Rolling CF'!$7:$7,0)) -> 0 | ... V44: =INDEX('Rolling CF'!$1:$1048576,MATCH($B44,'Rolling CF'!$C:$C,0),MATCH(V$7,'Rolling CF'!$7:$7,0)) -> 0
B45: Dues & Subscriptions | C45: Trailing 6 Week Average | D45: =INDEX('Rolling CF'!$1:$1048576,MATCH($B45,'Rolling CF'!$C:$C,0),MATCH(D$7,'Rolling CF'!$7:$7,0)) -> -310 | E45: =INDEX('Rolling CF'!$1:$1048576,MATCH($B45,'Rolling CF'!$C:$C,0),MATCH(E$7,'Rolling CF'!$7:$7,0)) -> -310 | F45: =INDEX('Rolling CF'!$1:$1048576,MATCH($B45,'Rolling CF'!$C:$C,0),MATCH(F$7,'Rolling CF'!$7:$7,0)) -> -310 | G45: =INDEX('Rolling CF'!$1:$1048576,MATCH($B45,'Rolling CF'!$C:$C,0),MATCH(G$7,'Rolling CF'!$7:$7,0)) -> -310 | H45: =INDEX('Rolling CF'!$1:$1048576,MATCH($B45,'Rolling CF'!$C:$C,0),MATCH(H$7,'Rolling CF'!$7:$7,0)) -> -310 | I45: =INDEX('Rolling CF'!$1:$1048576,MATCH($B45,'Rolling CF'!$C:$C,0),MATCH(I$7,'Rolling CF'!$7:$7,0)) -> -310 | J45: =INDEX('Rolling CF'!$1:$1048576,MATCH($B45,'Rolling CF'!$C:$C,0),MATCH(J$7,'Rolling CF'!$7:$7,0)) -> -310 | K45: =INDEX('Rolling CF'!$1:$1048576,MATCH($B45,'Rolling CF'!$C:$C,0),MATCH(K$7,'Rolling CF'!$7:$7,0)) -> -310 | ... V45: =INDEX('Rolling CF'!$1:$1048576,MATCH($B45,'Rolling CF'!$C:$C,0),MATCH(V$7,'Rolling CF'!$7:$7,0)) -> -310
B46: Insurance | C46: Enter Manually | D46: =INDEX('Rolling CF'!$1:$1048576,MATCH($B46,'Rolling CF'!$C:$C,0),MATCH(D$7,'Rolling CF'!$7:$7,0)) -> 0 | E46: =INDEX('Rolling CF'!$1:$1048576,MATCH($B46,'Rolling CF'!$C:$C,0),MATCH(E$7,'Rolling CF'!$7:$7,0)) -> 0 | F46: =INDEX('Rolling CF'!$1:$1048576,MATCH($B46,'Rolling CF'!$C:$C,0),MATCH(F$7,'Rolling CF'!$7:$7,0)) -> 0 | G46: =INDEX('Rolling CF'!$1:$1048576,MATCH($B46,'Rolling CF'!$C:$C,0),MATCH(G$7,'Rolling CF'!$7:$7,0)) -> 0 | H46: =INDEX('Rolling CF'!$1:$1048576,MATCH($B46,'Rolling CF'!$C:$C,0),MATCH(H$7,'Rolling CF'!$7:$7,0)) -> 0 | I46: =INDEX('Rolling CF'!$1:$1048576,MATCH($B46,'Rolling CF'!$C:$C,0),MATCH(I$7,'Rolling CF'!$7:$7,0)) -> 0 | J46: =INDEX('Rolling CF'!$1:$1048576,MATCH($B46,'Rolling CF'!$C:$C,0),MATCH(J$7,'Rolling CF'!$7:$7,0)) -> 0 | K46: =INDEX('Rolling CF'!$1:$1048576,MATCH($B46,'Rolling CF'!$C:$C,0),MATCH(K$7,'Rolling CF'!$7:$7,0)) -> 0 | ... V46: =INDEX('Rolling CF'!$1:$1048576,MATCH($B46,'Rolling CF'!$C:$C,0),MATCH(V$7,'Rolling CF'!$7:$7,0)) -> 0
B47: Lease Payments | C47: Trailing 6 Week Average | D47: =INDEX('Rolling CF'!$1:$1048576,MATCH($B47,'Rolling CF'!$C:$C,0),MATCH(D$7,'Rolling CF'!$7:$7,0)) -> -1350 | E47: =INDEX('Rolling CF'!$1:$1048576,MATCH($B47,'Rolling CF'!$C:$C,0),MATCH(E$7,'Rolling CF'!$7:$7,0)) -> 0 | F47: =INDEX('Rolling CF'!$1:$1048576,MATCH($B47,'Rolling CF'!$C:$C,0),MATCH(F$7,'Rolling CF'!$7:$7,0)) -> 0 | G47: =INDEX('Rolling CF'!$1:$1048576,MATCH($B47,'Rolling CF'!$C:$C,0),MATCH(G$7,'Rolling CF'!$7:$7,0)) -> -1350 | H47: =INDEX('Rolling CF'!$1:$1048576,MATCH($B47,'Rolling CF'!$C:$C,0),MATCH(H$7,'Rolling CF'!$7:$7,0)) -> -1350 | I47: =INDEX('Rolling CF'!$1:$1048576,MATCH($B47,'Rolling CF'!$C:$C,0),MATCH(I$7,'Rolling CF'!$7:$7,0)) -> 0 | J47: =INDEX('Rolling CF'!$1:$1048576,MATCH($B47,'Rolling CF'!$C:$C,0),MATCH(J$7,'Rolling CF'!$7:$7,0)) -> -675 | K47: =INDEX('Rolling CF'!$1:$1048576,MATCH($B47,'Rolling CF'!$C:$C,0),MATCH(K$7,'Rolling CF'!$7:$7,0)) -> -562.5 | ... V47: =INDEX('Rolling CF'!$1:$1048576,MATCH($B47,'Rolling CF'!$C:$C,0),MATCH(V$7,'Rolling CF'!$7:$7,0)) -> -645.00429
B48: Marketing | C48: Trailing 6 Week Average | D48: =INDEX('Rolling CF'!$1:$1048576,MATCH($B48,'Rolling CF'!$C:$C,0),MATCH(D$7,'Rolling CF'!$7:$7,0)) -> -1510 | E48: =INDEX('Rolling CF'!$1:$1048576,MATCH($B48,'Rolling CF'!$C:$C,0),MATCH(E$7,'Rolling CF'!$7:$7,0)) -> -1020 | F48: =INDEX('Rolling CF'!$1:$1048576,MATCH($B48,'Rolling CF'!$C:$C,0),MATCH(F$7,'Rolling CF'!$7:$7,0)) -> 0 | G48: =INDEX('Rolling CF'!$1:$1048576,MATCH($B48,'Rolling CF'!$C:$C,0),MATCH(G$7,'Rolling CF'!$7:$7,0)) -> 0 | H48: =INDEX('Rolling CF'!$1:$1048576,MATCH($B48,'Rolling CF'!$C:$C,0),MATCH(H$7,'Rolling CF'!$7:$7,0)) -> -1510 | I48: =INDEX('Rolling CF'!$1:$1048576,MATCH($B48,'Rolling CF'!$C:$C,0),MATCH(I$7,'Rolling CF'!$7:$7,0)) -> 0 | J48: =INDEX('Rolling CF'!$1:$1048576,MATCH($B48,'Rolling CF'!$C:$C,0),MATCH(J$7,'Rolling CF'!$7:$7,0)) -> -673.33333 | K48: =INDEX('Rolling CF'!$1:$1048576,MATCH($B48,'Rolling CF'!$C:$C,0),MATCH(K$7,'Rolling CF'!$7:$7,0)) -> -533.88889 | ... V48: =INDEX('Rolling CF'!$1:$1048576,MATCH($B48,'Rolling CF'!$C:$C,0),MATCH(V$7,'Rolling CF'!$7:$7,0)) -> -530.37388
B49: Phone & Internet | C49: Enter Manually | D49: =INDEX('Rolling CF'!$1:$1048576,MATCH($B49,'Rolling CF'!$C:$C,0),MATCH(D$7,'Rolling CF'!$7:$7,0)) -> 0 | E49: =INDEX('Rolling CF'!$1:$1048576,MATCH($B49,'Rolling CF'!$C:$C,0),MATCH(E$7,'Rolling CF'!$7:$7,0)) -> 0 | F49: =INDEX('Rolling CF'!$1:$1048576,MATCH($B49,'Rolling CF'!$C:$C,0),MATCH(F$7,'Rolling CF'!$7:$7,0)) -> 0 | G49: =INDEX('Rolling CF'!$1:$1048576,MATCH($B49,'Rolling CF'!$C:$C,0),MATCH(G$7,'Rolling CF'!$7:$7,0)) -> 0 | H49: =INDEX('Rolling CF'!$1:$1048576,MATCH($B49,'Rolling CF'!$C:$C,0),MATCH(H$7,'Rolling CF'!$7:$7,0)) -> 0 | I49: =INDEX('Rolling CF'!$1:$1048576,MATCH($B49,'Rolling CF'!$C:$C,0),MATCH(I$7,'Rolling CF'!$7:$7,0)) -> 0 | J49: =INDEX('Rolling CF'!$1:$1048576,MATCH($B49,'Rolling CF'!$C:$C,0),MATCH(J$7,'Rolling CF'!$7:$7,0)) -> 0 | K49: =INDEX('Rolling CF'!$1:$1048576,MATCH($B49,'Rolling CF'!$C:$C,0),MATCH(K$7,'Rolling CF'!$7:$7,0)) -> 0 | ... V49: =INDEX('Rolling CF'!$1:$1048576,MATCH($B49,'Rolling CF'!$C:$C,0),MATCH(V$7,'Rolling CF'!$7:$7,0)) -> 0
B50: Professional Fees | C50: $5k each Month | D50: =INDEX('Rolling CF'!$1:$1048576,MATCH($B50,'Rolling CF'!$C:$C,0),MATCH(D$7,'Rolling CF'!$7:$7,0)) -> -5000 | E50: =INDEX('Rolling CF'!$1:$1048576,MATCH($B50,'Rolling CF'!$C:$C,0),MATCH(E$7,'Rolling CF'!$7:$7,0)) -> 0 | F50: =INDEX('Rolling CF'!$1:$1048576,MATCH($B50,'Rolling CF'!$C:$C,0),MATCH(F$7,'Rolling CF'!$7:$7,0)) -> 0 | G50: =INDEX('Rolling CF'!$1:$1048576,MATCH($B50,'Rolling CF'!$C:$C,0),MATCH(G$7,'Rolling CF'!$7:$7,0)) -> 0 | H50: =INDEX('Rolling CF'!$1:$1048576,MATCH($B50,'Rolling CF'!$C:$C,0),MATCH(H$7,'Rolling CF'!$7:$7,0)) -> 0 | I50: =INDEX('Rolling CF'!$1:$1048576,MATCH($B50,'Rolling CF'!$C:$C,0),MATCH(I$7,'Rolling CF'!$7:$7,0)) -> -5000 | J50: =INDEX('Rolling CF'!$1:$1048576,MATCH($B50,'Rolling CF'!$C:$C,0),MATCH(J$7,'Rolling CF'!$7:$7,0)) -> 0 | K50: =INDEX('Rolling CF'!$1:$1048576,MATCH($B50,'Rolling CF'!$C:$C,0),MATCH(K$7,'Rolling CF'!$7:$7,0)) -> 0 | ... V50: =INDEX('Rolling CF'!$1:$1048576,MATCH($B50,'Rolling CF'!$C:$C,0),MATCH(V$7,'Rolling CF'!$7:$7,0)) -> 0
B51: Rent | C51: Enter Manually | D51: =INDEX('Rolling CF'!$1:$1048576,MATCH($B51,'Rolling CF'!$C:$C,0),MATCH(D$7,'Rolling CF'!$7:$7,0)) -> 0 | E51: =INDEX('Rolling CF'!$1:$1048576,MATCH($B51,'Rolling CF'!$C:$C,0),MATCH(E$7,'Rolling CF'!$7:$7,0)) -> 0 | F51: =INDEX('Rolling CF'!$1:$1048576,MATCH($B51,'Rolling CF'!$C:$C,0),MATCH(F$7,'Rolling CF'!$7:$7,0)) -> 0 | G51: =INDEX('Rolling CF'!$1:$1048576,MATCH($B51,'Rolling CF'!$C:$C,0),MATCH(G$7,'Rolling CF'!$7:$7,0)) -> 0 | H51: =INDEX('Rolling CF'!$1:$1048576,MATCH($B51,'Rolling CF'!$C:$C,0),MATCH(H$7,'Rolling CF'!$7:$7,0)) -> 0 | I51: =INDEX('Rolling CF'!$1:$1048576,MATCH($B51,'Rolling CF'!$C:$C,0),MATCH(I$7,'Rolling CF'!$7:$7,0)) -> 0 | J51: =INDEX('Rolling CF'!$1:$1048576,MATCH($B51,'Rolling CF'!$C:$C,0),MATCH(J$7,'Rolling CF'!$7:$7,0)) -> 0 | K51: =INDEX('Rolling CF'!$1:$1048576,MATCH($B51,'Rolling CF'!$C:$C,0),MATCH(K$7,'Rolling CF'!$7:$7,0)) -> 0 | ... V51: =INDEX('Rolling CF'!$1:$1048576,MATCH($B51,'Rolling CF'!$C:$C,0),MATCH(V$7,'Rolling CF'!$7:$7,0)) -> 0
B52: Repairs & Maintenance | C52: Enter Manually | D52: =INDEX('Rolling CF'!$1:$1048576,MATCH($B52,'Rolling CF'!$C:$C,0),MATCH(D$7,'Rolling CF'!$7:$7,0)) -> 0 | E52: =INDEX('Rolling CF'!$1:$1048576,MATCH($B52,'Rolling CF'!$C:$C,0),MATCH(E$7,'Rolling CF'!$7:$7,0)) -> 0 | F52: =INDEX('Rolling CF'!$1:$1048576,MATCH($B52,'Rolling CF'!$C:$C,0),MATCH(F$7,'Rolling CF'!$7:$7,0)) -> 0 | G52: =INDEX('Rolling CF'!$1:$1048576,MATCH($B52,'Rolling CF'!$C:$C,0),MATCH(G$7,'Rolling CF'!$7:$7,0)) -> 0 | H52: =INDEX('Rolling CF'!$1:$1048576,MATCH($B52,'Rolling CF'!$C:$C,0),MATCH(H$7,'Rolling CF'!$7:$7,0)) -> 0 | I52: =INDEX('Rolling CF'!$1:$1048576,MATCH($B52,'Rolling CF'!$C:$C,0),MATCH(I$7,'Rolling CF'!$7:$7,0)) -> 0 | J52: =INDEX('Rolling CF'!$1:$1048576,MATCH($B52,'Rolling CF'!$C:$C,0),MATCH(J$7,'Rolling CF'!$7:$7,0)) -> 0 | K52: =INDEX('Rolling CF'!$1:$1048576,MATCH($B52,'Rolling CF'!$C:$C,0),MATCH(K$7,'Rolling CF'!$7:$7,0)) -> 0 | ... V52: =INDEX('Rolling CF'!$1:$1048576,MATCH($B52,'Rolling CF'!$C:$C,0),MATCH(V$7,'Rolling CF'!$7:$7,0)) -> 0
... B60: Other Operating Outflows | C60: Trailing 6 Week Average | D60: =INDEX('Rolling CF'!$1:$1048576,MATCH($B60,'Rolling CF'!$C:$C,0),MATCH(D$7,'Rolling CF'!$7:$7,0)) -> -2570 | E60: =INDEX('Rolling CF'!$1:$1048576,MATCH($B60,'Rolling CF'!$C:$C,0),MATCH(E$7,'Rolling CF'!$7:$7,0)) -> 0 | F60: =INDEX('Rolling CF'!$1:$1048576,MATCH($B60,'Rolling CF'!$C:$C,0),MATCH(F$7,'Rolling CF'!$7:$7,0)) -> 0 | G60: =INDEX('Rolling CF'!$1:$1048576,MATCH($B60,'Rolling CF'!$C:$C,0),MATCH(G$7,'Rolling CF'!$7:$7,0)) -> 0 | H60: =INDEX('Rolling CF'!$1:$1048576,MATCH($B60,'Rolling CF'!$C:$C,0),MATCH(H$7,'Rolling CF'!$7:$7,0)) -> -1270 | I60: =INDEX('Rolling CF'!$1:$1048576,MATCH($B60,'Rolling CF'!$C:$C,0),MATCH(I$7,'Rolling CF'!$7:$7,0)) -> -1580 | J60: =INDEX('Rolling CF'!$1:$1048576,MATCH($B60,'Rolling CF'!$C:$C,0),MATCH(J$7,'Rolling CF'!$7:$7,0)) -> -903.33333 | K60: =INDEX('Rolling CF'!$1:$1048576,MATCH($B60,'Rolling CF'!$C:$C,0),MATCH(K$7,'Rolling CF'!$7:$7,0)) -> -625.55556 | ... V60: =INDEX('Rolling CF'!$1:$1048576,MATCH($B60,'Rolling CF'!$C:$C,0),MATCH(V$7,'Rolling CF'!$7:$7,0)) -> -866.79278
B62: Total Operating Cash Outflows | D62: =SUM(D41:D61) -> -374900 | E62: =SUM(E41:E61) -> -124910 | F62: =SUM(F41:F61) -> -180410 | G62: =SUM(G41:G61) -> -66850 | H62: =SUM(H41:H61) -> -166200 | I62: =SUM(I41:I61) -> -483870 | J62: =SUM(J41:J61) -> -51111.667 | K62: =SUM(K41:K61) -> -210073.61 | ... V62: =SUM(V41:V61) -> -44762.955
B64: Non-operating Cash Outflows
B65: Capital Expenditures | C65: Enter Manually | D65: =INDEX('Rolling CF'!$1:$1048576,MATCH($B65,'Rolling CF'!$C:$C,0),MATCH(D$7,'Rolling CF'!$7:$7,0)) -> 0 | E65: =INDEX('Rolling CF'!$1:$1048576,MATCH($B65,'Rolling CF'!$C:$C,0),MATCH(E$7,'Rolling CF'!$7:$7,0)) -> 0 | F65: =INDEX('Rolling CF'!$1:$1048576,MATCH($B65,'Rolling CF'!$C:$C,0),MATCH(F$7,'Rolling CF'!$7:$7,0)) -> 0 | G65: =INDEX('Rolling CF'!$1:$1048576,MATCH($B65,'Rolling CF'!$C:$C,0),MATCH(G$7,'Rolling CF'!$7:$7,0)) -> 0 | H65: =INDEX('Rolling CF'!$1:$1048576,MATCH($B65,'Rolling CF'!$C:$C,0),MATCH(H$7,'Rolling CF'!$7:$7,0)) -> 0 | I65: =INDEX('Rolling CF'!$1:$1048576,MATCH($B65,'Rolling CF'!$C:$C,0),MATCH(I$7,'Rolling CF'!$7:$7,0)) -> 0 | J65: =INDEX('Rolling CF'!$1:$1048576,MATCH($B65,'Rolling CF'!$C:$C,0),MATCH(J$7,'Rolling CF'!$7:$7,0)) -> 0 | K65: =INDEX('Rolling CF'!$1:$1048576,MATCH($B65,'Rolling CF'!$C:$C,0),MATCH(K$7,'Rolling CF'!$7:$7,0)) -> 0 | ... V65: =INDEX('Rolling CF'!$1:$1048576,MATCH($B65,'Rolling CF'!$C:$C,0),MATCH(V$7,'Rolling CF'!$7:$7,0)) -> 0
B66: Debt Proceeds | C66: Enter Manually | D66: =INDEX('Rolling CF'!$1:$1048576,MATCH($B66,'Rolling CF'!$C:$C,0),MATCH(D$7,'Rolling CF'!$7:$7,0)) -> 0 | E66: =INDEX('Rolling CF'!$1:$1048576,MATCH($B66,'Rolling CF'!$C:$C,0),MATCH(E$7,'Rolling CF'!$7:$7,0)) -> 0 | F66: =INDEX('Rolling CF'!$1:$1048576,MATCH($B66,'Rolling CF'!$C:$C,0),MATCH(F$7,'Rolling CF'!$7:$7,0)) -> 0 | G66: =INDEX('Rolling CF'!$1:$1048576,MATCH($B66,'Rolling CF'!$C:$C,0),MATCH(G$7,'Rolling CF'!$7:$7,0)) -> 0 | H66: =INDEX('Rolling CF'!$1:$1048576,MATCH($B66,'Rolling CF'!$C:$C,0),MATCH(H$7,'Rolling CF'!$7:$7,0)) -> 0 | I66: =INDEX('Rolling CF'!$1:$1048576,MATCH($B66,'Rolling CF'!$C:$C,0),MATCH(I$7,'Rolling CF'!$7:$7,0)) -> 0 | J66: =INDEX('Rolling CF'!$1:$1048576,MATCH($B66,'Rolling CF'!$C:$C,0),MATCH(J$7,'Rolling CF'!$7:$7,0)) -> 0 | K66: =INDEX('Rolling CF'!$1:$1048576,MATCH($B66,'Rolling CF'!$C:$C,0),MATCH(K$7,'Rolling CF'!$7:$7,0)) -> 0 | ... V66: =INDEX('Rolling CF'!$1:$1048576,MATCH($B66,'Rolling CF'!$C:$C,0),MATCH(V$7,'Rolling CF'!$7:$7,0)) -> 0
B67: Interest Payments | C67: Enter Manually | D67: =INDEX('Rolling CF'!$1:$1048576,MATCH($B67,'Rolling CF'!$C:$C,0),MATCH(D$7,'Rolling CF'!$7:$7,0)) -> 0 | E67: =INDEX('Rolling CF'!$1:$1048576,MATCH($B67,'Rolling CF'!$C:$C,0),MATCH(E$7,'Rolling CF'!$7:$7,0)) -> 0 | F67: =INDEX('Rolling CF'!$1:$1048576,MATCH($B67,'Rolling CF'!$C:$C,0),MATCH(F$7,'Rolling CF'!$7:$7,0)) -> 0 | G67: =INDEX('Rolling CF'!$1:$1048576,MATCH($B67,'Rolling CF'!$C:$C,0),MATCH(G$7,'Rolling CF'!$7:$7,0)) -> 0 | H67: =INDEX('Rolling CF'!$1:$1048576,MATCH($B67,'Rolling CF'!$C:$C,0),MATCH(H$7,'Rolling CF'!$7:$7,0)) -> 0 | I67: =INDEX('Rolling CF'!$1:$1048576,MATCH($B67,'Rolling CF'!$C:$C,0),MATCH(I$7,'Rolling CF'!$7:$7,0)) -> 0 | J67: =INDEX('Rolling CF'!$1:$1048576,MATCH($B67,'Rolling CF'!$C:$C,0),MATCH(J$7,'Rolling CF'!$7:$7,0)) -> 0 | K67: =INDEX('Rolling CF'!$1:$1048576,MATCH($B67,'Rolling CF'!$C:$C,0),MATCH(K$7,'Rolling CF'!$7:$7,0)) -> 0 | ... V67: =INDEX('Rolling CF'!$1:$1048576,MATCH($B67,'Rolling CF'!$C:$C,0),MATCH(V$7,'Rolling CF'!$7:$7,0)) -> 0
B68: Principal Payments | C68: Enter Manually | D68: =INDEX('Rolling CF'!$1:$1048576,MATCH($B68,'Rolling CF'!$C:$C,0),MATCH(D$7,'Rolling CF'!$7:$7,0)) -> 0 | E68: =INDEX('Rolling CF'!$1:$1048576,MATCH($B68,'Rolling CF'!$C:$C,0),MATCH(E$7,'Rolling CF'!$7:$7,0)) -> 0 | F68: =INDEX('Rolling CF'!$1:$1048576,MATCH($B68,'Rolling CF'!$C:$C,0),MATCH(F$7,'Rolling CF'!$7:$7,0)) -> 0 | G68: =INDEX('Rolling CF'!$1:$1048576,MATCH($B68,'Rolling CF'!$C:$C,0),MATCH(G$7,'Rolling CF'!$7:$7,0)) -> 0 | H68: =INDEX('Rolling CF'!$1:$1048576,MATCH($B68,'Rolling CF'!$C:$C,0),MATCH(H$7,'Rolling CF'!$7:$7,0)) -> 0 | I68: =INDEX('Rolling CF'!$1:$1048576,MATCH($B68,'Rolling CF'!$C:$C,0),MATCH(I$7,'Rolling CF'!$7:$7,0)) -> 0 | J68: =INDEX('Rolling CF'!$1:$1048576,MATCH($B68,'Rolling CF'!$C:$C,0),MATCH(J$7,'Rolling CF'!$7:$7,0)) -> 0 | K68: =INDEX('Rolling CF'!$1:$1048576,MATCH($B68,'Rolling CF'!$C:$C,0),MATCH(K$7,'Rolling CF'!$7:$7,0)) -> 0 | ... V68: =INDEX('Rolling CF'!$1:$1048576,MATCH($B68,'Rolling CF'!$C:$C,0),MATCH(V$7,'Rolling CF'!$7:$7,0)) -> 0
B69: Tax Distributions | C69: Trailing 6 Week Average | D69: =INDEX('Rolling CF'!$1:$1048576,MATCH($B69,'Rolling CF'!$C:$C,0),MATCH(D$7,'Rolling CF'!$7:$7,0)) -> -24740 | E69: =INDEX('Rolling CF'!$1:$1048576,MATCH($B69,'Rolling CF'!$C:$C,0),MATCH(E$7,'Rolling CF'!$7:$7,0)) -> -20220 | F69: =INDEX('Rolling CF'!$1:$1048576,MATCH($B69,'Rolling CF'!$C:$C,0),MATCH(F$7,'Rolling CF'!$7:$7,0)) -> -14200 | G69: =INDEX('Rolling CF'!$1:$1048576,MATCH($B69,'Rolling CF'!$C:$C,0),MATCH(G$7,'Rolling CF'!$7:$7,0)) -> -12680 | H69: =INDEX('Rolling CF'!$1:$1048576,MATCH($B69,'Rolling CF'!$C:$C,0),MATCH(H$7,'Rolling CF'!$7:$7,0)) -> -12340 | I69: =INDEX('Rolling CF'!$1:$1048576,MATCH($B69,'Rolling CF'!$C:$C,0),MATCH(I$7,'Rolling CF'!$7:$7,0)) -> -8560 | J69: =INDEX('Rolling CF'!$1:$1048576,MATCH($B69,'Rolling CF'!$C:$C,0),MATCH(J$7,'Rolling CF'!$7:$7,0)) -> -15456.667 | K69: =INDEX('Rolling CF'!$1:$1048576,MATCH($B69,'Rolling CF'!$C:$C,0),MATCH(K$7,'Rolling CF'!$7:$7,0)) -> -13909.444 | ... V69: =INDEX('Rolling CF'!$1:$1048576,MATCH($B69,'Rolling CF'!$C:$C,0),MATCH(V$7,'Rolling CF'!$7:$7,0)) -> -12988.889
B70: Equity Distributions | C70: Enter Manually | D70: =INDEX('Rolling CF'!$1:$1048576,MATCH($B70,'Rolling CF'!$C:$C,0),MATCH(D$7,'Rolling CF'!$7:$7,0)) -> 0 | E70: =INDEX('Rolling CF'!$1:$1048576,MATCH($B70,'Rolling CF'!$C:$C,0),MATCH(E$7,'Rolling CF'!$7:$7,0)) -> 0 | F70: =INDEX('Rolling CF'!$1:$1048576,MATCH($B70,'Rolling CF'!$C:$C,0),MATCH(F$7,'Rolling CF'!$7:$7,0)) -> 0 | G70: =INDEX('Rolling CF'!$1:$1048576,MATCH($B70,'Rolling CF'!$C:$C,0),MATCH(G$7,'Rolling CF'!$7:$7,0)) -> 0 | H70: =INDEX('Rolling CF'!$1:$1048576,MATCH($B70,'Rolling CF'!$C:$C,0),MATCH(H$7,'Rolling CF'!$7:$7,0)) -> 0 | I70: =INDEX('Rolling CF'!$1:$1048576,MATCH($B70,'Rolling CF'!$C:$C,0),MATCH(I$7,'Rolling CF'!$7:$7,0)) -> 0 | J70: =INDEX('Rolling CF'!$1:$1048576,MATCH($B70,'Rolling CF'!$C:$C,0),MATCH(J$7,'Rolling CF'!$7:$7,0)) -> 0 | K70: =INDEX('Rolling CF'!$1:$1048576,MATCH($B70,'Rolling CF'!$C:$C,0),MATCH(K$7,'Rolling CF'!$7:$7,0)) -> 0 | ... V70: =INDEX('Rolling CF'!$1:$1048576,MATCH($B70,'Rolling CF'!$C:$C,0),MATCH(V$7,'Rolling CF'!$7:$7,0)) -> 0
B71: Equity Contributions | C71: Enter Manually | D71: =INDEX('Rolling CF'!$1:$1048576,MATCH($B71,'Rolling CF'!$C:$C,0),MATCH(D$7,'Rolling CF'!$7:$7,0)) -> 0 | E71: =INDEX('Rolling CF'!$1:$1048576,MATCH($B71,'Rolling CF'!$C:$C,0),MATCH(E$7,'Rolling CF'!$7:$7,0)) -> 0 | F71: =INDEX('Rolling CF'!$1:$1048576,MATCH($B71,'Rolling CF'!$C:$C,0),MATCH(F$7,'Rolling CF'!$7:$7,0)) -> 0 | G71: =INDEX('Rolling CF'!$1:$1048576,MATCH($B71,'Rolling CF'!$C:$C,0),MATCH(G$7,'Rolling CF'!$7:$7,0)) -> 0 | H71: =INDEX('Rolling CF'!$1:$1048576,MATCH($B71,'Rolling CF'!$C:$C,0),MATCH(H$7,'Rolling CF'!$7:$7,0)) -> 0 | I71: =INDEX('Rolling CF'!$1:$1048576,MATCH($B71,'Rolling CF'!$C:$C,0),MATCH(I$7,'Rolling CF'!$7:$7,0)) -> 0 | J71: =INDEX('Rolling CF'!$1:$1048576,MATCH($B71,'Rolling CF'!$C:$C,0),MATCH(J$7,'Rolling CF'!$7:$7,0)) -> 0 | K71: =INDEX('Rolling CF'!$1:$1048576,MATCH($B71,'Rolling CF'!$C:$C,0),MATCH(K$7,'Rolling CF'!$7:$7,0)) -> 0 | ... V71: =INDEX('Rolling CF'!$1:$1048576,MATCH($B71,'Rolling CF'!$C:$C,0),MATCH(V$7,'Rolling CF'!$7:$7,0)) -> 0
B72: Other Non-operating Outflows | C72: Trailing 6 Week Average | D72: =INDEX('Rolling CF'!$1:$1048576,MATCH($B72,'Rolling CF'!$C:$C,0),MATCH(D$7,'Rolling CF'!$7:$7,0)) -> -8580 | E72: =INDEX('Rolling CF'!$1:$1048576,MATCH($B72,'Rolling CF'!$C:$C,0),MATCH(E$7,'Rolling CF'!$7:$7,0)) -> 0 | F72: =INDEX('Rolling CF'!$1:$1048576,MATCH($B72,'Rolling CF'!$C:$C,0),MATCH(F$7,'Rolling CF'!$7:$7,0)) -> -1140 | G72: =INDEX('Rolling CF'!$1:$1048576,MATCH($B72,'Rolling CF'!$C:$C,0),MATCH(G$7,'Rolling CF'!$7:$7,0)) -> 0 | H72: =INDEX('Rolling CF'!$1:$1048576,MATCH($B72,'Rolling CF'!$C:$C,0),MATCH(H$7,'Rolling CF'!$7:$7,0)) -> 0 | I72: =INDEX('Rolling CF'!$1:$1048576,MATCH($B72,'Rolling CF'!$C:$C,0),MATCH(I$7,'Rolling CF'!$7:$7,0)) -> -3260 | J72: =INDEX('Rolling CF'!$1:$1048576,MATCH($B72,'Rolling CF'!$C:$C,0),MATCH(J$7,'Rolling CF'!$7:$7,0)) -> -2163.3333 | K72: =INDEX('Rolling CF'!$1:$1048576,MATCH($B72,'Rolling CF'!$C:$C,0),MATCH(K$7,'Rolling CF'!$7:$7,0)) -> -1093.8889 | ... V72: =INDEX('Rolling CF'!$1:$1048576,MATCH($B72,'Rolling CF'!$C:$C,0),MATCH(V$7,'Rolling CF'!$7:$7,0)) -> -1492.2525
...

Sheet Variance Analysis
C2: Master Error Check Cell | D2: ='Error Checking'!$B$2 -> 0
C4: Actual / Forecast | E4: Actual | F4: Actual | G4: Actual | H4: Actual | I4: Actual | J4: Actual | K4: Actual | L4: Forecast | M4: Forecast | N4: Forecast | O4: Forecast | P4: Forecast | Q4: Forecast | R4: Forecast | S4: Forecast | T4: Forecast | U4: Forecast | V4: Forecast | W4: Forecast
C5: Week Number | E5: 1 | F5: =E5+1 -> 2 | G5: =F5+1 -> 3 | H5: =G5+1 -> 4 | I5: =H5+1 -> 5 | J5: =I5+1 -> 6 | K5: =J5+1 -> 7 | L5: =K5+1 -> 8 | M5: =L5+1 -> 9 | ... W5: =V5+1 -> 19
C6: Week Beginning | E6: =E7-6 -> 45221 | F6: =F7-6 -> 45228 | G6: =G7-6 -> 45235 | H6: =H7-6 -> 45242 | I6: =I7-6 -> 45249 | J6: =J7-6 -> 45256 | K6: =K7-6 -> 45263 | L6: =L7-6 -> 45270 | ... W6: =W7-6 -> 45347
B7: Variance Tagging | C7: Week Ending | E7: =F6-1 -> 45227 | F7: =G6-1 -> 45234 | G7: =H6-1 -> 45241 | H7: =I6-1 -> 45248 | I7: =J6-1 -> 45255 | J7: =K6-1 -> 45262 | K7: =L6-1 -> 45269 | L7: =M6-1 -> 45276 | ... V7: =W6-1 -> 45346 | W7: =MAX('13 weeks CF'!7:7) -> 45353
C9: Bridge
B10: Ending Cash | C10: Last Week's Ending Cash | E10: =INDEX('13 weeks CF'!$12:$12,MATCH(E$7,'13 weeks CF'!$7:$7,0)) -> 210210 | F10: =INDEX('13 weeks CF'!$12:$12,MATCH(F$7,'13 weeks CF'!$7:$7,0)) -> 174090 | G10: =INDEX('13 weeks CF'!$12:$12,MATCH(G$7,'13 weeks CF'!$7:$7,0)) -> 239110 | H10: =INDEX('13 weeks CF'!$12:$12,MATCH(H$7,'13 weeks CF'!$7:$7,0)) -> 43360 | I10: =INDEX('13 weeks CF'!$12:$12,MATCH(I$7,'13 weeks CF'!$7:$7,0)) -> 325260 | J10: =INDEX('13 weeks CF'!$12:$12,MATCH(J$7,'13 weeks CF'!$7:$7,0)) -> 215160 | K10: =INDEX('13 weeks CF'!$12:$12,MATCH(K$7,'13 weeks CF'!$7:$7,0)) -> 112041.67 | L10: =INDEX('13 weeks CF'!$12:$12,MATCH(L$7,'13 weeks CF'!$7:$7,0)) -> 156995.28 | ... W10: =INDEX('13 weeks CF'!$12:$12,MATCH(W$7,'13 weeks CF'!$7:$7,0)) -> 291189.57
C11: Difference in Invoiced AR + New Revenue | E11: =SUM($E24:E24) -> 0 | F11: =SUM($E24:F24) -> 0 | G11: =SUM($E24:G24) -> 0 | H11: =SUM($E24:H24) -> 0 | I11: =SUM($E24:I24) -> 0 | J11: =SUM($E24:J24) -> 0 | K11: =SUM($E24:K24) -> 59470 | L11: =SUM($E24:L24) -> 59470 | ... W11: =SUM($E24:W24) -> -142130
C12: Difference in Accounts Payable | E12: =SUM($E28:E28) -> 0 | F12: =SUM($E28:F28) -> 0 | G12: =SUM($E28:G28) -> 0 | H12: =SUM($E28:H28) -> 0 | I12: =SUM($E28:I28) -> 0 | J12: =SUM($E28:J28) -> 0 | K12: =SUM($E28:K28) -> -88940 | L12: =SUM($E28:L28) -> -87140 | ... W12: =SUM($E28:W28) -> -271640
C13: Difference in Credit Cards | E13: =SUM($E32:E32) -> 0 | F13: =SUM($E32:F32) -> 0 | G13: =SUM($E32:G32) -> 0 | H13: =SUM($E32:H32) -> 0 | I13: =SUM($E32:I32) -> 0 | J13: =SUM($E32:J32) -> 0 | K13: =SUM($E32:K32) -> -210 | L13: =SUM($E32:L32) -> -210 | ... W13: =SUM($E32:W32) -> -128310
C14: Difference in Other Ops | E14: =SUM($E36:E36) -> 0 | F14: =SUM($E36:F36) -> 0 | G14: =SUM($E36:G36) -> 0 | H14: =SUM($E36:H36) -> 0 | I14: =SUM($E36:I36) -> 0 | J14: =SUM($E36:J36) -> 0 | K14: =SUM($E36:K36) -> 19210 | L14: =SUM($E36:L36) -> 22496.667 | ... W14: =SUM($E36:W36) -> 82258.893
C15: Difference in Non Ops | E15: =SUM($E40:E40) -> 0 | F15: =SUM($E40:F40) -> 0 | G15: =SUM($E40:G40) -> 0 | H15: =SUM($E40:H40) -> 0 | I15: =SUM($E40:I40) -> 0 | J15: =SUM($E40:J40) -> 0 | K15: =SUM($E40:K40) -> 7368.3333 | L15: =SUM($E40:L40) -> 8596.3889 | ... W15: =SUM($E40:W40) -> 30926.409
C17: Net Difference | E17: =SUM(E11:E16) -> 0 | F17: =SUM(F11:F16) -> 0 | G17: =SUM(G11:G16) -> 0 | H17: =SUM(H11:H16) -> 0 | I17: =SUM(I11:I16) -> 0 | J17: =SUM(J11:J16) -> 0 | K17: =SUM(K11:K16) -> -3101.6667 | L17: =SUM(L11:L16) -> 3213.0556 | ... W17: =SUM(W11:W16) -> -428894.7
C18: This Week's Ending Cash | E18: =SUM(E10,E17) -> 210210 | F18: =SUM(F10,F17) -> 174090 | G18: =SUM(G10,G17) -> 239110 | H18: =SUM(H10,H17) -> 43360 | I18: =SUM(I10,I17) -> 325260 | J18: =SUM(J10,J17) -> 215160 | K18: =SUM(K10,K17) -> 108940 | L18: =SUM(L10,L17) -> 160208.33 | ... W18: =SUM(W10,W17) -> -137705.13
C19: This Week's Ending Cash, per Forecast | E19: =INDEX('Rolling CF'!$12:$12,MATCH(E$7,'Rolling CF'!$7:$7,0)) -> 210210 | F19: =INDEX('Rolling CF'!$12:$12,MATCH(F$7,'Rolling CF'!$7:$7,0)) -> 174090 | G19: =INDEX('Rolling CF'!$12:$12,MATCH(G$7,'Rolling CF'!$7:$7,0)) -> 239110 | H19: =INDEX('Rolling CF'!$12:$12,MATCH(H$7,'Rolling CF'!$7:$7,0)) -> 43360 | I19: =INDEX('Rolling CF'!$12:$12,MATCH(I$7,'Rolling CF'!$7:$7,0)) -> 325260 | J19: =INDEX('Rolling CF'!$12:$12,MATCH(J$7,'Rolling CF'!$7:$7,0)) -> 215160 | K19: =INDEX('Rolling CF'!$12:$12,MATCH(K$7,'Rolling CF'!$7:$7,0)) -> 108940 | L19: =INDEX('Rolling CF'!$12:$12,MATCH(L$7,'Rolling CF'!$7:$7,0)) -> 160208.33 | ... W19: =INDEX('Rolling CF'!$12:$12,MATCH(W$7,'Rolling CF'!$7:$7,0)) -> -137705.13
C20: Difference | E20: =ROUND(E18-E19,2) -> 0 | F20: =ROUND(F18-F19,2) -> 0 | G20: =ROUND(G18-G19,2) -> 0 | H20: =ROUND(H18-H19,2) -> 0 | I20: =ROUND(I18-I19,2) -> 0 | J20: =ROUND(J18-J19,2) -> 0 | K20: =ROUND(K18-K19,2) -> 0 | L20: =ROUND(L18-L19,2) -> 0 | ... W20: =ROUND(W18-W19,2) -> 0
B22: Invoiced AR + New Revenue | C22: ="Last Week's "&B22 -> Last Week's Invoiced AR + New Revenue | E22: {=SUMPRODUCT('13 weeks CF'!$E$10:$X$59*('13 weeks CF'!$E$7:$X$7=E$7)*('13 weeks CF'!$B$10:$B$59=$B22))} -> 0 | F22: {=SUMPRODUCT('13 weeks CF'!$E$10:$X$59*('13 weeks CF'!$E$7:$X$7=F$7)*('13 weeks CF'!$B$10:$B$59=$B22))} -> 372100 | G22: {=SUMPRODUCT('13 weeks CF'!$E$10:$X$59*('13 weeks CF'!$E$7:$X$7=G$7)*('13 weeks CF'!$B$10:$B$59=$B22))} -> 210150 | H22: {=SUMPRODUCT('13 weeks CF'!$E$10:$X$59*('13 weeks CF'!$E$7:$X$7=H$7)*('13 weeks CF'!$B$10:$B$59=$B22))} -> 0 | I22: {=SUMPRODUCT('13 weeks CF'!$E$10:$X$59*('13 weeks CF'!$E$7:$X$7=I$7)*('13 weeks CF'!$B$10:$B$59=$B22))} -> 361430 | J22: {=SUMPRODUCT('13 weeks CF'!$E$10:$X$59*('13 weeks CF'!$E$7:$X$7=J$7)*('13 weeks CF'!$B$10:$B$59=$B22))} -> 68440 | K22: {=SUMPRODUCT('13 weeks CF'!$E$10:$X$59*('13 weeks CF'!$E$7:$X$7=K$7)*('13 weeks CF'!$B$10:$B$59=$B22))} -> 330000 | L22: {=SUMPRODUCT('13 weeks CF'!$E$10:$X$59*('13 weeks CF'!$E$7:$X$7=L$7)*('13 weeks CF'!$B$10:$B$59=$B22))} -> 120000 | ... W22: {=SUMPRODUCT('13 weeks CF'!$E$10:$X$59*('13 weeks CF'!$E$7:$X$7=W$7)*('13 weeks CF'!$B$10:$B$59=$B22))} -> 0
B23: Invoiced AR + New Revenue | C23: ="This Week's "&B23 -> This Week's Invoiced AR + New Revenue | E23: {=SUMPRODUCT('Rolling CF'!$E$10:$Y$59*('Rolling CF'!$E$7:$Y$7=E$7)*('Rolling CF'!$B$10:$B$59=$B23))} -> 0 | F23: {=SUMPRODUCT('Rolling CF'!$E$10:$Y$59*('Rolling CF'!$E$7:$Y$7=F$7)*('Rolling CF'!$B$10:$B$59=$B23))} -> 372100 | G23: {=SUMPRODUCT('Rolling CF'!$E$10:$Y$59*('Rolling CF'!$E$7:$Y$7=G$7)*('Rolling CF'!$B$10:$B$59=$B23))} -> 210150 | H23: {=SUMPRODUCT('Rolling CF'!$E$10:$Y$59*('Rolling CF'!$E$7:$Y$7=H$7)*('Rolling CF'!$B$10:$B$59=$B23))} -> 0 | I23: {=SUMPRODUCT('Rolling CF'!$E$10:$Y$59*('Rolling CF'!$E$7:$Y$7=I$7)*('Rolling CF'!$B$10:$B$59=$B23))} -> 361430 | J23: {=SUMPRODUCT('Rolling CF'!$E$10:$Y$59*('Rolling CF'!$E$7:$Y$7=J$7)*('Rolling CF'!$B$10:$B$59=$B23))} -> 68440 | K23: {=SUMPRODUCT('Rolling CF'!$E$10:$Y$59*('Rolling CF'!$E$7:$Y$7=K$7)*('Rolling CF'!$B$10:$B$59=$B23))} -> 389470 | L23: {=SUMPRODUCT('Rolling CF'!$E$10:$Y$59*('Rolling CF'!$E$7:$Y$7=L$7)*('Rolling CF'!$B$10:$B$59=$B23))} -> 120000 | ... W23: {=SUMPRODUCT('Rolling CF'!$E$10:$Y$59*('Rolling CF'!$E$7:$Y$7=W$7)*('Rolling CF'!$B$10:$B$59=$B23))} -> 0
B24: Invoiced AR + New Revenue | C24: ="Difference in "&B24 -> Difference in Invoiced AR + New Revenue | E24: =E23-E22 -> 0 | F24: =F23-F22 -> 0 | G24: =G23-G22 -> 0 | H24: =H23-H22 -> 0 | I24: =I23-I22 -> 0 | J24: =J23-J22 -> 0 | K24: =K23-K22 -> 59470 | L24: =L23-L22 -> 0 | ... W24: =W23-W22 -> 0
B26: Accounts Payable | C26: ="Last Week's "&B26 -> Last Week's Accounts Payable | E26: {=SUMPRODUCT('13 weeks CF'!$E$10:$X$59*('13 weeks CF'!$E$7:$X$7=E$7)*('13 weeks CF'!$B$10:$B$59=$B26))} -> -33620 | F26: {=SUMPRODUCT('13 weeks CF'!$E$10:$X$59*('13 weeks CF'!$E$7:$X$7=F$7)*('13 weeks CF'!$B$10:$B$59=$B26))} -> -83210 | G26: {=SUMPRODUCT('13 weeks CF'!$E$10:$X$59*('13 weeks CF'!$E$7:$X$7=G$7)*('13 weeks CF'!$B$10:$B$59=$B26))} -> -69810 | H26: {=SUMPRODUCT('13 weeks CF'!$E$10:$X$59*('13 weeks CF'!$E$7:$X$7=H$7)*('13 weeks CF'!$B$10:$B$59=$B26))} -> -40140 | I26: {=SUMPRODUCT('13 weeks CF'!$E$10:$X$59*('13 weeks CF'!$E$7:$X$7=I$7)*('13 weeks CF'!$B$10:$B$59=$B26))} -> -18680 | J26: {=SUMPRODUCT('13 weeks CF'!$E$10:$X$59*('13 weeks CF'!$E$7:$X$7=J$7)*('13 weeks CF'!$B$10:$B$59=$B26))} -> -88580 | K26: {=SUMPRODUCT('13 weeks CF'!$E$10:$X$59*('13 weeks CF'!$E$7:$X$7=K$7)*('13 weeks CF'!$B$10:$B$59=$B26))} -> -800 | L26: {=SUMPRODUCT('13 weeks CF'!$E$10:$X$59*('13 weeks CF'!$E$7:$X$7=L$7)*('13 weeks CF'!$B$10:$B$59=$B26))} -> -1800 | ... W26: {=SUMPRODUCT('13 weeks CF'!$E$10:$X$59*('13 weeks CF'!$E$7:$X$7=W$7)*('13 weeks CF'!$B$10:$B$59=$B26))} -> 0
B27: Accounts Payable | C27: ="This Week's "&B27 -> This Week's Accounts Payable | E27: {=SUMPRODUCT('Rolling CF'!$E$10:$Y$59*('Rolling CF'!$E$7:$Y$7=E$7)*('Rolling CF'!$B$10:$B$59=$B27))} -> -33620 | F27: {=SUMPRODUCT('Rolling CF'!$E$10:$Y$59*('Rolling CF'!$E$7:$Y$7=F$7)*('Rolling CF'!$B$10:$B$59=$B27))} -> -83210 | G27: {=SUMPRODUCT('Rolling CF'!$E$10:$Y$59*('Rolling CF'!$E$7:$Y$7=G$7)*('Rolling CF'!$B$10:$B$59=$B27))} -> -69810 | H27: {=SUMPRODUCT('Rolling CF'!$E$10:$Y$59*('Rolling CF'!$E$7:$Y$7=H$7)*('Rolling CF'!$B$10:$B$59=$B27))} -> -40140 | I27: {=SUMPRODUCT('Rolling CF'!$E$10:$Y$59*('Rolling CF'!$E$7:$Y$7=I$7)*('Rolling CF'!$B$10:$B$59=$B27))} -> -18680 | J27: {=SUMPRODUCT('Rolling CF'!$E$10:$Y$59*('Rolling CF'!$E$7:$Y$7=J$7)*('Rolling CF'!$B$10:$B$59=$B27))} -> -88580 | K27: {=SUMPRODUCT('Rolling CF'!$E$10:$Y$59*('Rolling CF'!$E$7:$Y$7=K$7)*('Rolling CF'!$B$10:$B$59=$B27))} -> -89740 | L27: {=SUMPRODUCT('Rolling CF'!$E$10:$Y$59*('Rolling CF'!$E$7:$Y$7=L$7)*('Rolling CF'!$B$10:$B$59=$B27))} -> 0 | ... W27: {=SUMPRODUCT('Rolling CF'!$E$10:$Y$59*('Rolling CF'!$E$7:$Y$7=W$7)*('Rolling CF'!$B$10:$B$59=$B27))} -> 0
B28: Accounts Payable | C28: ="Difference in "&B28 -> Difference in Accounts Payable | E28: =E27-E26 -> 0 | F28: =F27-F26 -> 0 | G28: =G27-G26 -> 0 | H28: =H27-H26 -> 0 | I28: =I27-I26 -> 0 | J28: =J27-J26 -> 0 | K28: =K27-K26 -> -88940 | L28: =L27-L26 -> 1800 | ... W28: =W27-W26 -> 0
B30: Credit Cards | C30: ="Last Week's "&B30 -> Last Week's Credit Cards | E30: {=SUMPRODUCT('13 weeks CF'!$E$10:$X$59*('13 weeks CF'!$E$7:$X$7=E$7)*('13 weeks CF'!$B$10:$B$59=$B30))} -> 0 | F30: {=SUMPRODUCT('13 weeks CF'!$E$10:$X$59*('13 weeks CF'!$E$7:$X$7=F$7)*('13 weeks CF'!$B$10:$B$59=$B30))} -> -194090 | G30: {=SUMPRODUCT('13 weeks CF'!$E$10:$X$59*('13 weeks CF'!$E$7:$X$7=G$7)*('13 weeks CF'!$B$10:$B$59=$B30))} -> 0 | H30: {=SUMPRODUCT('13 weeks CF'!$E$10:$X$59*('13 weeks CF'!$E$7:$X$7=H$7)*('13 weeks CF'!$B$10:$B$59=$B30))} -> -100000 | I30: {=SUMPRODUCT('13 weeks CF'!$E$10:$X$59*('13 weeks CF'!$E$7:$X$7=I$7)*('13 weeks CF'!$B$10:$B$59=$B30))} -> 0 | J30: {=SUMPRODUCT('13 weeks CF'!$E$10:$X$59*('13 weeks CF'!$E$7:$X$7=J$7)*('13 weeks CF'!$B$10:$B$59=$B30))} -> -32000 | K30: {=SUMPRODUCT('13 weeks CF'!$E$10:$X$59*('13 weeks CF'!$E$7:$X$7=K$7)*('13 weeks CF'!$B$10:$B$59=$B30))} -> -350000 | L30: {=SUMPRODUCT('13 weeks CF'!$E$10:$X$59*('13 weeks CF'!$E$7:$X$7=L$7)*('13 weeks CF'!$B$10:$B$59=$B30))} -> 0 | ... W30: {=SUMPRODUCT('13 weeks CF'!$E$10:$X$59*('13 weeks CF'!$E$7:$X$7=W$7)*('13 weeks CF'!$B$10:$B$59=$B30))} -> -210000
B31: Credit Cards | C31: ="This Week's "&B31 -> This Week's Credit Cards | E31: {=SUMPRODUCT('Rolling CF'!$E$10:$Y$59*('Rolling CF'!$E$7:$Y$7=E$7)*('Rolling CF'!$B$10:$B$59=$B31))} -> 0 | F31: {=SUMPRODUCT('Rolling CF'!$E$10:$Y$59*('Rolling CF'!$E$7:$Y$7=F$7)*('Rolling CF'!$B$10:$B$59=$B31))} -> -194090 | G31: {=SUMPRODUCT('Rolling CF'!$E$10:$Y$59*('Rolling CF'!$E$7:$Y$7=G$7)*('Rolling CF'!$B$10:$B$59=$B31))} -> 0 | H31: {=SUMPRODUCT('Rolling CF'!$E$10:$Y$59*('Rolling CF'!$E$7:$Y$7=H$7)*('Rolling CF'!$B$10:$B$59=$B31))} -> -100000 | I31: {=SUMPRODUCT('Rolling CF'!$E$10:$Y$59*('Rolling CF'!$E$7:$Y$7=I$7)*('Rolling CF'!$B$10:$B$59=$B31))} -> 0 | J31: {=SUMPRODUCT('Rolling CF'!$E$10:$Y$59*('Rolling CF'!$E$7:$Y$7=J$7)*('Rolling CF'!$B$10:$B$59=$B31))} -> -32000 | K31: {=SUMPRODUCT('Rolling CF'!$E$10:$Y$59*('Rolling CF'!$E$7:$Y$7=K$7)*('Rolling CF'!$B$10:$B$59=$B31))} -> -350210 | L31: {=SUMPRODUCT('Rolling CF'!$E$10:$Y$59*('Rolling CF'!$E$7:$Y$7=L$7)*('Rolling CF'!$B$10:$B$59=$B31))} -> 0 | ... W31: {=SUMPRODUCT('Rolling CF'!$E$10:$Y$59*('Rolling CF'!$E$7:$Y$7=W$7)*('Rolling CF'!$B$10:$B$59=$B31))} -> -216000
B32: Credit Cards | C32: ="Difference in "&B32 -> Difference in Credit Cards | E32: =E31-E30 -> 0 | F32: =F31-F30 -> 0 | G32: =G31-G30 -> 0 | H32: =H31-H30 -> 0 | I32: =I31-I30 -> 0 | J32: =J31-J30 -> 0 | K32: =K31-K30 -> -210 | L32: =L31-L30 -> 0 | ... W32: =W31-W30 -> -6000
B34: Other Ops | C34: ="Last Week's "&B34 -> Last Week's Other Ops | E34: {=SUMPRODUCT('13 weeks CF'!$E$10:$X$59*('13 weeks CF'!$E$7:$X$7=E$7)*('13 weeks CF'!$B$10:$B$59=$B34))} -> -80520 | F34: {=SUMPRODUCT('13 weeks CF'!$E$10:$X$59*('13 weeks CF'!$E$7:$X$7=F$7)*('13 weeks CF'!$B$10:$B$59=$B34))} -> -97600 | G34: {=SUMPRODUCT('13 weeks CF'!$E$10:$X$59*('13 weeks CF'!$E$7:$X$7=G$7)*('13 weeks CF'!$B$10:$B$59=$B34))} -> -55100 | H34: {=SUMPRODUCT('13 weeks CF'!$E$10:$X$59*('13 weeks CF'!$E$7:$X$7=H$7)*('13 weeks CF'!$B$10:$B$59=$B34))} -> -40270 | I34: {=SUMPRODUCT('13 weeks CF'!$E$10:$X$59*('13 weeks CF'!$E$7:$X$7=I$7)*('13 weeks CF'!$B$10:$B$59=$B34))} -> -48170 | J34: {=SUMPRODUCT('13 weeks CF'!$E$10:$X$59*('13 weeks CF'!$E$7:$X$7=J$7)*('13 weeks CF'!$B$10:$B$59=$B34))} -> -45620 | K34: {=SUMPRODUCT('13 weeks CF'!$E$10:$X$59*('13 weeks CF'!$E$7:$X$7=K$7)*('13 weeks CF'!$B$10:$B$59=$B34))} -> -63130 | L34: {=SUMPRODUCT('13 weeks CF'!$E$10:$X$59*('13 weeks CF'!$E$7:$X$7=L$7)*('13 weeks CF'!$B$10:$B$59=$B34))} -> -54398.333 | ... W34: {=SUMPRODUCT('13 weeks CF'!$E$10:$X$59*('13 weeks CF'!$E$7:$X$7=W$7)*('13 weeks CF'!$B$10:$B$59=$B34))} -> -62464.987
B35: Other Ops | C35: ="This Week's "&B35 -> This Week's Other Ops | E35: {=SUMPRODUCT('Rolling CF'!$E$10:$Y$59*('Rolling CF'!$E$7:$Y$7=E$7)*('Rolling CF'!$B$10:$B$59=$B35))} -> -80520 | F35: {=SUMPRODUCT('Rolling CF'!$E$10:$Y$59*('Rolling CF'!$E$7:$Y$7=F$7)*('Rolling CF'!$B$10:$B$59=$B35))} -> -97600 | G35: {=SUMPRODUCT('Rolling CF'!$E$10:$Y$59*('Rolling CF'!$E$7:$Y$7=G$7)*('Rolling CF'!$B$10:$B$59=$B35))} -> -55100 | H35: {=SUMPRODUCT('Rolling CF'!$E$10:$Y$59*('Rolling CF'!$E$7:$Y$7=H$7)*('Rolling CF'!$B$10:$B$59=$B35))} -> -40270 | I35: {=SUMPRODUCT('Rolling CF'!$E$10:$Y$59*('Rolling CF'!$E$7:$Y$7=I$7)*('Rolling CF'!$B$10:$B$59=$B35))} -> -48170 | J35: {=SUMPRODUCT('Rolling CF'!$E$10:$Y$59*('Rolling CF'!$E$7:$Y$7=J$7)*('Rolling CF'!$B$10:$B$59=$B35))} -> -45620 | K35: {=SUMPRODUCT('Rolling CF'!$E$10:$Y$59*('Rolling CF'!$E$7:$Y$7=K$7)*('Rolling CF'!$B$10:$B$59=$B35))} -> -43920 | L35: {=SUMPRODUCT('Rolling CF'!$E$10:$Y$59*('Rolling CF'!$E$7:$Y$7=L$7)*('Rolling CF'!$B$10:$B$59=$B35))} -> -51111.667 | ... W35: {=SUMPRODUCT('Rolling CF'!$E$10:$Y$59*('Rolling CF'!$E$7:$Y$7=W$7)*('Rolling CF'!$B$10:$B$59=$B35))} -> -56729.815
B36: Other Ops | C36: ="Difference in "&B36 -> Difference in Other Ops | E36: =E35-E34 -> 0 | F36: =F35-F34 -> 0 | G36: =G35-G34 -> 0 | H36: =H35-H34 -> 0 | I36: =I35-I34 -> 0 | J36: =J35-J34 -> 0 | K36: =K35-K34 -> 19210 | L36: =L35-L34 -> 3286.6667 | ... W36: =W35-W34 -> 5735.1718
B38: Non Ops | C38: ="Last Week's "&B38 -> Last Week's Non Ops | E38: {=SUMPRODUCT('13 weeks CF'!$E$10:$X$59*('13 weeks CF'!$E$7:$X$7=E$7)*('13 weeks CF'!$B$10:$B$59=$B38))} -> -21230 | F38: {=SUMPRODUCT('13 weeks CF'!$E$10:$X$59*('13 weeks CF'!$E$7:$X$7=F$7)*('13 weeks CF'!$B$10:$B$59=$B38))} -> -33320 | G38: {=SUMPRODUCT('13 weeks CF'!$E$10:$X$59*('13 weeks CF'!$E$7:$X$7=G$7)*('13 weeks CF'!$B$10:$B$59=$B38))} -> -20220 | H38: {=SUMPRODUCT('13 weeks CF'!$E$10:$X$59*('13 weeks CF'!$E$7:$X$7=H$7)*('13 weeks CF'!$B$10:$B$59=$B38))} -> -15340 | I38: {=SUMPRODUCT('13 weeks CF'!$E$10:$X$59*('13 weeks CF'!$E$7:$X$7=I$7)*('13 weeks CF'!$B$10:$B$59=$B38))} -> -12680 | J38: {=SUMPRODUCT('13 weeks CF'!$E$10:$X$59*('13 weeks CF'!$E$7:$X$7=J$7)*('13 weeks CF'!$B$10:$B$59=$B38))} -> -12340 | K38: {=SUMPRODUCT('13 weeks CF'!$E$10:$X$59*('13 weeks CF'!$E$7:$X$7=K$7)*('13 weeks CF'!$B$10:$B$59=$B38))} -> -19188.333 | L38: {=SUMPRODUCT('13 weeks CF'!$E$10:$X$59*('13 weeks CF'!$E$7:$X$7=L$7)*('13 weeks CF'!$B$10:$B$59=$B38))} -> -18848.056 | ... W38: {=SUMPRODUCT('13 weeks CF'!$E$10:$X$59*('13 weeks CF'!$E$7:$X$7=W$7)*('13 weeks CF'!$B$10:$B$59=$B38))} -> -16618.479
B39: Non Ops | C39: ="This Week's "&B39 -> This Week's Non Ops | E39: {=SUMPRODUCT('Rolling CF'!$E$10:$Y$59*('Rolling CF'!$E$7:$Y$7=E$7)*('Rolling CF'!$B$10:$B$59=$B39))} -> -21230 | F39: {=SUMPRODUCT('Rolling CF'!$E$10:$Y$59*('Rolling CF'!$E$7:$Y$7=F$7)*('Rolling CF'!$B$10:$B$59=$B39))} -> -33320 | G39: {=SUMPRODUCT('Rolling CF'!$E$10:$Y$59*('Rolling CF'!$E$7:$Y$7=G$7)*('Rolling CF'!$B$10:$B$59=$B39))} -> -20220 | H39: {=SUMPRODUCT('Rolling CF'!$E$10:$Y$59*('Rolling CF'!$E$7:$Y$7=H$7)*('Rolling CF'!$B$10:$B$59=$B39))} -> -15340 | I39: {=SUMPRODUCT('Rolling CF'!$E$10:$Y$59*('Rolling CF'!$E$7:$Y$7=I$7)*('Rolling CF'!$B$10:$B$59=$B39))} -> -12680 | J39: {=SUMPRODUCT('Rolling CF'!$E$10:$Y$59*('Rolling CF'!$E$7:$Y$7=J$7)*('Rolling CF'!$B$10:$B$59=$B39))} -> -12340 | K39: {=SUMPRODUCT('Rolling CF'!$E$10:$Y$59*('Rolling CF'!$E$7:$Y$7=K$7)*('Rolling CF'!$B$10:$B$59=$B39))} -> -11820 | L39: {=SUMPRODUCT('Rolling CF'!$E$10:$Y$59*('Rolling CF'!$E$7:$Y$7=L$7)*('Rolling CF'!$B$10:$B$59=$B39))} -> -17620 | ... W39: {=SUMPRODUCT('Rolling CF'!$E$10:$Y$59*('Rolling CF'!$E$7:$Y$7=W$7)*('Rolling CF'!$B$10:$B$59=$B39))} -> -14475.545
B40: Non Ops | C40: ="Difference in "&B40 -> Difference in Non Ops | E40: =E39-E38 -> 0 | F40: =F39-F38 -> 0 | G40: =G39-G38 -> 0 | H40: =H39-H38 -> 0 | I40: =I39-I38 -> 0 | J40: =J39-J38 -> 0 | K40: =K39-K38 -> 7368.3333 | L40: =L39-L38 -> 1228.0556 | ... W40: =W39-W38 -> 2142.934
C42: Commentary
C43: What Changed: | I43: Why it Changed: | Q43: What to do Next:
C44: Pulsetech can't pay | I44: Liquidity crisis | Q44: Reach out to AP team
C45: Whirlix can't pay | I45: Liquidity crisis | Q45: Reach out to AP team
C46: Astratech had larger AP balance than expected | I46: [to discuss] | Q46: [to discuss]

Sheet Rolling CF
E1: =SUMPRODUCT([result range]*([date range]=[date])*([category range]=[category]))
C2: Master Error Check Cell | D2: ='Error Checking'!$B$2 -> 0
C4: Actual / Forecast | E4: Actual | F4: Actual | G4: Actual | H4: Actual | I4: Actual | J4: Actual | K4: Actual | L4: Forecast | M4: Forecast | N4: Forecast | O4: Forecast | P4: Forecast | Q4: Forecast | R4: Forecast | S4: Forecast | T4: Forecast | U4: Forecast | V4: Forecast | W4: Forecast | X4: Forecast
C5: Week Number | E5: 1 | F5: =E5+1 -> 2 | G5: =F5+1 -> 3 | H5: =G5+1 -> 4 | I5: =H5+1 -> 5 | J5: =I5+1 -> 6 | K5: =J5+1 -> 7 | L5: =K5+1 -> 8 | M5: =L5+1 -> 9 | ... X5: =W5+1 -> 20
C6: Week Beginning | E6: 45221 | F6: =E7+1 -> 45228 | G6: =F7+1 -> 45235 | H6: =G7+1 -> 45242 | I6: =H7+1 -> 45249 | J6: =I7+1 -> 45256 | K6: =J7+1 -> 45263 | L6: =K7+1 -> 45270 | M6: =L7+1 -> 45277 | ... X6: =W7+1 -> 45354
B7: Variance Tagging | C7: Week Ending | D7: Forecast Methodology | E7: =E6+6 -> 45227 | F7: =F6+6 -> 45234 | G7: =G6+6 -> 45241 | H7: =H6+6 -> 45248 | I7: =I6+6 -> 45255 | J7: =J6+6 -> 45262 | K7: =K6+6 -> 45269 | L7: =L6+6 -> 45276 | ... X7: =X6+6 -> 45360 | Y7: Placeholder
C9: Cash Balance
C10: Beginning Cash | E10: 345580 | F10: =E12 -> 210210 | G10: =F12 -> 174090 | H10: =G12 -> 239110 | I10: =H12 -> 43360 | J10: =I12 -> 325260 | K10: =J12 -> 215160 | L10: =K12 -> 108940 | M10: =L12 -> 160208.33 | ... X10: =W12 -> -137705.13
C11: Change in Cash | E11: =E59 -> -135370 | F11: =F59 -> -36120 | G11: =G59 -> 65020 | H11: =H59 -> -195750 | I11: =I59 -> 281900 | J11: =J59 -> -110100 | K11: =K59 -> -106220 | L11: =L59 -> 51268.333 | ... X11: =X59 -> -59244.097
B12: Ending Cash | C12: Ending Cash | E12: =SUM(E10:E11) -> 210210 | F12: =SUM(F10:F11) -> 174090 | G12: =SUM(G10:G11) -> 239110 | H12: =SUM(H10:H11) -> 43360 | I12: =SUM(I10:I11) -> 325260 | J12: =SUM(J10:J11) -> 215160 | K12: =SUM(K10:K11) -> 108940 | L12: =SUM(L10:L11) -> 160208.33 | ... X12: =SUM(X10:X11) -> -196949.22
C13: Per Data | E13: 210210 | F13: 174090 | G13: 239110 | H13: 43360 | I13: 325260 | J13: 215160 | K13: 108940
C14: Double-Check | E14: =IF(E$4="Forecast",0,E13-E12) -> 0 | F14: =IF(F$4="Forecast",0,F13-F12) -> 0 | G14: =IF(G$4="Forecast",0,G13-G12) -> 0 | H14: =IF(H$4="Forecast",0,H13-H12) -> 0 | I14: =IF(I$4="Forecast",0,I13-I12) -> 0 | J14: =IF(J$4="Forecast",0,J13-J12) -> 0 | K14: =IF(K$4="Forecast",0,K13-K12) -> 0 | L14: =IF(L$4="Forecast",0,L13-L12) -> 0 | ... X14: =IF(X$4="Forecast",0,X13-X12) -> 0
C15: Last Week's Forecast | E15: 210210 | F15: 174090 | G15: 239110 | H15: 43360 | I15: 325260 | J15: 215160 | K15: 112041.67 | L15: 156995.28 | M15: 399451.16 | N15: 415303.02 | O15: 382731.85 | P15: 316373.83 | Q15: 519442.8 | R15: 532142.99 | S15: 472334.27 | T15: 279031.46 | U15: 412252.87 | V15: 580273.04 | W15: 291189.57
C17: Cash Inflows
B18: Invoiced AR + New Revenue | C18: Invoiced AR + New Revenue | D18: See AR Aging Schedule | E18: =SUMIFS(Actuals!$I:$I,Actuals!$A:$A,E$7,Actuals!$C:$C,$C18) -> 0 | F18: =SUMIFS(Actuals!$I:$I,Actuals!$A:$A,F$7,Actuals!$C:$C,$C18) -> 372100 | G18: =SUMIFS(Actuals!$I:$I,Actuals!$A:$A,G$7,Actuals!$C:$C,$C18) -> 210150 | H18: =SUMIFS(Actuals!$I:$I,Actuals!$A:$A,H$7,Actuals!$C:$C,$C18) -> 0 | I18: =SUMIFS(Actuals!$I:$I,Actuals!$A:$A,I$7,Actuals!$C:$C,$C18) -> 361430 | J18: =SUMIFS(Actuals!$I:$I,Actuals!$A:$A,J$7,Actuals!$C:$C,$C18) -> 68440 | K18: =SUMIFS(Actuals!$I:$I,Actuals!$A:$A,K$7,Actuals!$C:$C,$C18) -> 389470 | L18: =SUMIFS('AR Aging 02'!$B:$B,'AR Aging 02'!$A:$A,L$7) -> 120000 | M18: =SUMIFS('AR Aging 02'!$B:$B,'AR Aging 02'!$A:$A,M$7) -> 554000 | N18: =SUMIFS('AR Aging 02'!$B:$B,'AR Aging 02'!$A:$A,N$7) -> 80000 | O18: =SUMIFS('AR Aging 02'!$B:$B,'AR Aging 02'!$A:$A,O$7) -> 198400 | P18: =SUMIFS('AR Aging 02'!$B:$B,'AR Aging 02'!$A:$A,P$7) -> 0 | Q18: =SUMIFS('AR Aging 02'!$B:$B,'AR Aging 02'!$A:$A,Q$7) -> 271800 | R18: =SUMIFS('AR Aging 02'!$B:$B,'AR Aging 02'!$A:$A,R$7) -> 80000 | S18: =SUMIFS('AR Aging 02'!$B:$B,'AR Aging 02'!$A:$A,S$7) -> 0 | ... X18: =SUMIFS('AR Aging 02'!$B:$B,'AR Aging 02'!$A:$A,X$7) -> 0
B19: Invoiced AR + New Revenue | C19: Other Inflows | D19: Enter Manually | E19: =SUMIFS(Actuals!$I:$I,Actuals!$A:$A,E$7,Actuals!$C:$C,$C19) -> 0 | F19: =SUMIFS(Actuals!$I:$I,Actuals!$A:$A,F$7,Actuals!$C:$C,$C19) -> 0 | G19: =SUMIFS(Actuals!$I:$I,Actuals!$A:$A,G$7,Actuals!$C:$C,$C19) -> 0 | H19: =SUMIFS(Actuals!$I:$I,Actuals!$A:$A,H$7,Actuals!$C:$C,$C19) -> 0 | I19: =SUMIFS(Actuals!$I:$I,Actuals!$A:$A,I$7,Actuals!$C:$C,$C19) -> 0 | J19: =SUMIFS(Actuals!$I:$I,Actuals!$A:$A,J$7,Actuals!$C:$C,$C19) -> 0 | K19: =SUMIFS(Actuals!$I:$I,Actuals!$A:$A,K$7,Actuals!$C:$C,$C19) -> 0
C21: Total Cash Inflows | E21: =SUM(E18:E20) -> 0 | F21: =SUM(F18:F20) -> 372100 | G21: =SUM(G18:G20) -> 210150 | H21: =SUM(H18:H20) -> 0 | I21: =SUM(I18:I20) -> 361430 | J21: =SUM(J18:J20) -> 68440 | K21: =SUM(K18:K20) -> 389470 | L21: =SUM(L18:L20) -> 120000 | ... X21: =SUM(X18:X20) -> 0
C23: Operating Cash Outflows
B24: Accounts Payable | C24: Accounts Payable | D24: See AP Aging Schedule | E24: =SUMIFS(Actuals!$I:$I,Actuals!$A:$A,E$7,Actuals!$C:$C,$C24) -> -33620 | F24: =SUMIFS(Actuals!$I:$I,Actuals!$A:$A,F$7,Actuals!$C:$C,$C24) -> -83210 | G24: =SUMIFS(Actuals!$I:$I,Actuals!$A:$A,G$7,Actuals!$C:$C,$C24) -> -69810 | H24: =SUMIFS(Actuals!$I:$I,Actuals!$A:$A,H$7,Actuals!$C:$C,$C24) -> -40140 | I24: =SUMIFS(Actuals!$I:$I,Actuals!$A:$A,I$7,Actuals!$C:$C,$C24) -> -18680 | J24: =SUMIFS(Actuals!$I:$I,Actuals!$A:$A,J$7,Actuals!$C:$C,$C24) -> -88580 | K24: =SUMIFS(Actuals!$I:$I,Actuals!$A:$A,K$7,Actuals!$C:$C,$C24) -> -89740 | L24: =-SUMIFS('AP Aging 02'!$B:$B,'AP Aging 02'!$A:$A,L$7,'AP Aging 02'!$D:$D,"<>Yes") -> 0 | M24: =-SUMIFS('AP Aging 02'!$B:$B,'AP Aging 02'!$A:$A,M$7,'AP Aging 02'!$D:$D,"<>Yes") -> -164600 | N24: =-SUMIFS('AP Aging 02'!$B:$B,'AP Aging 02'!$A:$A,N$7,'AP Aging 02'!$D:$D,"<>Yes") -> 0 | O24: =-SUMIFS('AP Aging 02'!$B:$B,'AP Aging 02'!$A:$A,O$7,'AP Aging 02'!$D:$D,"<>Yes") -> 0 | P24: =-SUMIFS('AP Aging 02'!$B:$B,'AP Aging 02'!$A:$A,P$7,'AP Aging 02'!$D:$D,"<>Yes") -> 0 | Q24: =-SUMIFS('AP Aging 02'!$B:$B,'AP Aging 02'!$A:$A,Q$7,'AP Aging 02'!$D:$D,"<>Yes") -> -50000 | R24: =-SUMIFS('AP Aging 02'!$B:$B,'AP Aging 02'!$A:$A,R$7,'AP Aging 02'!$D:$D,"<>Yes") -> 0 | S24: =-SUMIFS('AP Aging 02'!$B:$B,'AP Aging 02'!$A:$A,S$7,'AP Aging 02'!$D:$D,"<>Yes") -> 0 | ... X24: =-SUMIFS('AP Aging 02'!$B:$B,'AP Aging 02'!$A:$A,X$7,'AP Aging 02'!$D:$D,"<>Yes") -> 0
B25: Credit Cards | C25: Credit Cards | D25: See AP Aging Schedule | E25: =SUMIFS(Actuals!$I:$I,Actuals!$A:$A,E$7,Actuals!$C:$C,$C25) -> 0 | F25: =SUMIFS(Actuals!$I:$I,Actuals!$A:$A,F$7,Actuals!$C:$C,$C25) -> -194090 | G25: =SUMIFS(Actuals!$I:$I,Actuals!$A:$A,G$7,Actuals!$C:$C,$C25) -> 0 | H25: =SUMIFS(Actuals!$I:$I,Actuals!$A:$A,H$7,Actuals!$C:$C,$C25) -> -100000 | I25: =SUMIFS(Actuals!$I:$I,Actuals!$A:$A,I$7,Actuals!$C:$C,$C25) -> 0 | J25: =SUMIFS(Actuals!$I:$I,Actuals!$A:$A,J$7,Actuals!$C:$C,$C25) -> -32000 | K25: =SUMIFS(Actuals!$I:$I,Actuals!$A:$A,K$7,Actuals!$C:$C,$C25) -> -350210 | L25: =-SUMIFS('AP Aging 02'!$B:$B,'AP Aging 02'!$A:$A,L$7,'AP Aging 02'!$D:$D,"Yes") -> 0 | M25: =-SUMIFS('AP Aging 02'!$B:$B,'AP Aging 02'!$A:$A,M$7,'AP Aging 02'!$D:$D,"Yes") -> 0 | N25: =-SUMIFS('AP Aging 02'!$B:$B,'AP Aging 02'!$A:$A,N$7,'AP Aging 02'!$D:$D,"Yes") -> 0 | O25: =-SUMIFS('AP Aging 02'!$B:$B,'AP Aging 02'!$A:$A,O$7,'AP Aging 02'!$D:$D,"Yes") -> -153000 | P25: =-SUMIFS('AP Aging 02'!$B:$B,'AP Aging 02'!$A:$A,P$7,'AP Aging 02'!$D:$D,"Yes") -> 0 | Q25: =-SUMIFS('AP Aging 02'!$B:$B,'AP Aging 02'!$A:$A,Q$7,'AP Aging 02'!$D:$D,"Yes") -> 0 | R25: =-SUMIFS('AP Aging 02'!$B:$B,'AP Aging 02'!$A:$A,R$7,'AP Aging 02'!$D:$D,"Yes") -> 0 | S25: =-SUMIFS('AP Aging 02'!$B:$B,'AP Aging 02'!$A:$A,S$7,'AP Aging 02'!$D:$D,"Yes") -> -203600 | ... X25: =-SUMIFS('AP Aging 02'!$B:$B,'AP Aging 02'!$A:$A,X$7,'AP Aging 02'!$D:$D,"Yes") -> 0
B26: Other Ops | C26: Payroll | D26: Trailing 6 Week Average | E26: =SUMIFS(Actuals!$I:$I,Actuals!$A:$A,E$7,Actuals!$C:$C,$C26) -> -77830 | F26: =SUMIFS(Actuals!$I:$I,Actuals!$A:$A,F$7,Actuals!$C:$C,$C26) -> -78050 | G26: =SUMIFS(Actuals!$I:$I,Actuals!$A:$A,G$7,Actuals!$C:$C,$C26) -> -51670 | H26: =SUMIFS(Actuals!$I:$I,Actuals!$A:$A,H$7,Actuals!$C:$C,$C26) -> -39960 | I26: =SUMIFS(Actuals!$I:$I,Actuals!$A:$A,I$7,Actuals!$C:$C,$C26) -> -44380 | J26: =SUMIFS(Actuals!$I:$I,Actuals!$A:$A,J$7,Actuals!$C:$C,$C26) -> -35340 | K26: =SUMIFS(Actuals!$I:$I,Actuals!$A:$A,K$7,Actuals!$C:$C,$C26) -> -35660 | L26: =AVERAGE(F26:K26) -> -47510 | M26: =AVERAGE(G26:L26) -> -42420 | N26: =AVERAGE(H26:M26) -> -40878.333 | O26: =AVERAGE(I26:N26) -> -41031.389 | P26: =AVERAGE(J26:O26) -> -40473.287 | Q26: =AVERAGE(K26:P26) -> -41328.835 | R26: =AVERAGE(L26:Q26) -> -42273.641 | S26: =AVERAGE(M26:R26) -> -41400.914 | ... X26: =AVERAGE(R26:W26) -> -41500.77
B27: Other Ops | C27: Contractors | D27: Enter Manually | E27: =SUMIFS(Actuals!$I:$I,Actuals!$A:$A,E$7,Actuals!$C:$C,$C27) -> 0 | F27: =SUMIFS(Actuals!$I:$I,Actuals!$A:$A,F$7,Actuals!$C:$C,$C27) -> 0 | G27: =SUMIFS(Actuals!$I:$I,Actuals!$A:$A,G$7,Actuals!$C:$C,$C27) -> 0 | H27: =SUMIFS(Actuals!$I:$I,Actuals!$A:$A,H$7,Actuals!$C:$C,$C27) -> 0 | I27: =SUMIFS(Actuals!$I:$I,Actuals!$A:$A,I$7,Actuals!$C:$C,$C27) -> 0 | J27: =SUMIFS(Actuals!$I:$I,Actuals!$A:$A,J$7,Actuals!$C:$C,$C27) -> 0 | K27: =SUMIFS(Actuals!$I:$I,Actuals!$A:$A,K$7,Actuals!$C:$C,$C27) -> 0
B28: Other Ops | C28: Dues & Subscriptions | D28: Trailing 6 Week Average | E28: =SUMIFS(Actuals!$I:$I,Actuals!$A:$A,E$7,Actuals!$C:$C,$C28) -> -310 | F28: =SUMIFS(Actuals!$I:$I,Actuals!$A:$A,F$7,Actuals!$C:$C,$C28) -> -310 | G28: =SUMIFS(Actuals!$I:$I,Actuals!$A:$A,G$7,Actuals!$C:$C,$C28) -> -310 | H28: =SUMIFS(Actuals!$I:$I,Actuals!$A:$A,H$7,Actuals!$C:$C,$C28) -> -310 | I28: =SUMIFS(Actuals!$I:$I,Actuals!$A:$A,I$7,Actuals!$C:$C,$C28) -> -310 | J28: =SUMIFS(Actuals!$I:$I,Actuals!$A:$A,J$7,Actuals!$C:$C,$C28) -> -310 | K28: =SUMIFS(Actuals!$I:$I,Actuals!$A:$A,K$7,Actuals!$C:$C,$C28) -> -310 | L28: =AVERAGE(F28:K28) -> -310 | M28: =AVERAGE(G28:L28) -> -310 | N28: =AVERAGE(H28:M28) -> -310 | O28: =AVERAGE(I28:N28) -> -310 | P28: =AVERAGE(J28:O28) -> -310 | Q28: =AVERAGE(K28:P28) -> -310 | R28: =AVERAGE(L28:Q28) -> -310 | S28: =AVERAGE(M28:R28) -> -310 | ... X28: =AVERAGE(R28:W28) -> -310
B29: Other Ops | C29: Insurance | D29: Enter Manually | E29: =SUMIFS(Actuals!$I:$I,Actuals!$A:$A,E$7,Actuals!$C:$C,$C29) -> 0 | F29: =SUMIFS(Actuals!$I:$I,Actuals!$A:$A,F$7,Actuals!$C:$C,$C29) -> 0 | G29: =SUMIFS(Actuals!$I:$I,Actuals!$A:$A,G$7,Actuals!$C:$C,$C29) -> 0 | H29: =SUMIFS(Actuals!$I:$I,Actuals!$A:$A,H$7,Actuals!$C:$C,$C29) -> 0 | I29: =SUMIFS(Actuals!$I:$I,Actuals!$A:$A,I$7,Actuals!$C:$C,$C29) -> 0 | J29: =SUMIFS(Actuals!$I:$I,Actuals!$A:$A,J$7,Actuals!$C:$C,$C29) -> 0 | K29: =SUMIFS(Actuals!$I:$I,Actuals!$A:$A,K$7,Actuals!$C:$C,$C29) -> 0
